{
 "cells": [
  {
   "cell_type": "code",
   "execution_count": 1,
   "metadata": {
    "ExecuteTime": {
     "end_time": "2019-04-16T04:53:38.696618Z",
     "start_time": "2019-04-16T04:53:38.692442Z"
    },
    "pycharm": {
     "is_executing": false
    }
   },
   "outputs": [],
   "source": [
    "from MicropolisControlScript import Quimby\n",
    "import numpy as np\n",
    "from gi.repository import Gtk as gtk\n",
    "import json\n",
    "import random"
   ]
  },
  {
   "cell_type": "markdown",
   "metadata": {
    "pycharm": {}
   },
   "source": [
    "# Genetic Algorithm to build micropolis city"
   ]
  },
  {
   "cell_type": "code",
   "execution_count": 3,
   "metadata": {
    "ExecuteTime": {
     "end_time": "2019-04-16T05:10:08.500941Z",
     "start_time": "2019-04-16T05:10:08.233915Z"
    },
    "pycharm": {
     "is_executing": false
    }
   },
   "outputs": [],
   "source": [
    "q = Quimby(map_w=30,map_h=30,gen_size=100,n_population=100,n_steps_evaluation=10)"
   ]
  },
  {
   "cell_type": "code",
   "execution_count": 4,
   "metadata": {
    "pycharm": {
     "is_executing": false,
     "metadata": false,
     "name": "#%%\n"
    }
   },
   "outputs": [
    {
     "ename": "SystemError",
     "evalue": "<built-in function Micropolis_simTick> returned a result with an error set",
     "output_type": "error",
     "traceback": [
      "\u001b[0;31m---------------------------------------------------------------------------\u001b[0m",
      "\u001b[0;31mKeyboardInterrupt\u001b[0m                         Traceback (most recent call last)",
      "\u001b[0;32m~/ML_TERM/gym-micropolis-ga/micropolis/MicropolisCore/src/pyMicropolis/micropolisEngine/micropolisgenericengine.py\u001b[0m in \u001b[0;36minvokeCallback\u001b[0;34m(self, micropolis, name, *args)\u001b[0m\n\u001b[1;32m   1186\u001b[0m         \u001b[0;31m# In this case, micropolis is the same as self, so ignore it.\u001b[0m\u001b[0;34m\u001b[0m\u001b[0;34m\u001b[0m\u001b[0;34m\u001b[0m\u001b[0m\n\u001b[0;32m-> 1187\u001b[0;31m         \u001b[0mhandler\u001b[0m \u001b[0;34m=\u001b[0m \u001b[0mgetattr\u001b[0m\u001b[0;34m(\u001b[0m\u001b[0mself\u001b[0m\u001b[0;34m,\u001b[0m \u001b[0;34m'handle_'\u001b[0m \u001b[0;34m+\u001b[0m \u001b[0mname\u001b[0m\u001b[0;34m,\u001b[0m \u001b[0;32mNone\u001b[0m\u001b[0;34m)\u001b[0m\u001b[0;34m\u001b[0m\u001b[0;34m\u001b[0m\u001b[0m\n\u001b[0m\u001b[1;32m   1188\u001b[0m         \u001b[0;32mif\u001b[0m \u001b[0mhandler\u001b[0m\u001b[0;34m:\u001b[0m\u001b[0;34m\u001b[0m\u001b[0;34m\u001b[0m\u001b[0m\n",
      "\u001b[0;31mKeyboardInterrupt\u001b[0m: ",
      "\nThe above exception was the direct cause of the following exception:\n",
      "\u001b[0;31mSystemError\u001b[0m                               Traceback (most recent call last)",
      "\u001b[0;32m~/ML_TERM/gym-micropolis-ga/micropolis/MicropolisCore/src/pyMicropolis/micropolisEngine/micropolisgenericengine.py\u001b[0m in \u001b[0;36minvokeCallback\u001b[0;34m(self, micropolis, name, *args)\u001b[0m\n\u001b[1;32m   1186\u001b[0m         \u001b[0;31m# In this case, micropolis is the same as self, so ignore it.\u001b[0m\u001b[0;34m\u001b[0m\u001b[0;34m\u001b[0m\u001b[0;34m\u001b[0m\u001b[0m\n\u001b[0;32m-> 1187\u001b[0;31m         \u001b[0mhandler\u001b[0m \u001b[0;34m=\u001b[0m \u001b[0mgetattr\u001b[0m\u001b[0;34m(\u001b[0m\u001b[0mself\u001b[0m\u001b[0;34m,\u001b[0m \u001b[0;34m'handle_'\u001b[0m \u001b[0;34m+\u001b[0m \u001b[0mname\u001b[0m\u001b[0;34m,\u001b[0m \u001b[0;32mNone\u001b[0m\u001b[0;34m)\u001b[0m\u001b[0;34m\u001b[0m\u001b[0;34m\u001b[0m\u001b[0m\n\u001b[0m\u001b[1;32m   1188\u001b[0m         \u001b[0;32mif\u001b[0m \u001b[0mhandler\u001b[0m\u001b[0;34m:\u001b[0m\u001b[0;34m\u001b[0m\u001b[0;34m\u001b[0m\u001b[0m\n",
      "\u001b[0;31mSystemError\u001b[0m: <built-in function getattr> returned a result with an error set",
      "\nThe above exception was the direct cause of the following exception:\n",
      "\u001b[0;31mSystemError\u001b[0m                               Traceback (most recent call last)",
      "\u001b[0;32m~/ML_TERM/gym-micropolis-ga/micropolis/MicropolisCore/src/pyMicropolis/micropolisEngine/micropolisgenericengine.py\u001b[0m in \u001b[0;36minvokeCallback\u001b[0;34m(self, micropolis, name, *args)\u001b[0m\n\u001b[1;32m   1186\u001b[0m         \u001b[0;31m# In this case, micropolis is the same as self, so ignore it.\u001b[0m\u001b[0;34m\u001b[0m\u001b[0;34m\u001b[0m\u001b[0;34m\u001b[0m\u001b[0m\n\u001b[0;32m-> 1187\u001b[0;31m         \u001b[0mhandler\u001b[0m \u001b[0;34m=\u001b[0m \u001b[0mgetattr\u001b[0m\u001b[0;34m(\u001b[0m\u001b[0mself\u001b[0m\u001b[0;34m,\u001b[0m \u001b[0;34m'handle_'\u001b[0m \u001b[0;34m+\u001b[0m \u001b[0mname\u001b[0m\u001b[0;34m,\u001b[0m \u001b[0;32mNone\u001b[0m\u001b[0;34m)\u001b[0m\u001b[0;34m\u001b[0m\u001b[0;34m\u001b[0m\u001b[0m\n\u001b[0m\u001b[1;32m   1188\u001b[0m         \u001b[0;32mif\u001b[0m \u001b[0mhandler\u001b[0m\u001b[0;34m:\u001b[0m\u001b[0;34m\u001b[0m\u001b[0;34m\u001b[0m\u001b[0m\n",
      "\u001b[0;31mSystemError\u001b[0m: <built-in function getattr> returned a result with an error set",
      "\nThe above exception was the direct cause of the following exception:\n",
      "\u001b[0;31mSystemError\u001b[0m                               Traceback (most recent call last)",
      "\u001b[0;32m~/ML_TERM/gym-micropolis-ga/micropolis/MicropolisCore/src/pyMicropolis/micropolisEngine/micropolisgenericengine.py\u001b[0m in \u001b[0;36minvokeCallback\u001b[0;34m(self, micropolis, name, *args)\u001b[0m\n\u001b[1;32m   1186\u001b[0m         \u001b[0;31m# In this case, micropolis is the same as self, so ignore it.\u001b[0m\u001b[0;34m\u001b[0m\u001b[0;34m\u001b[0m\u001b[0;34m\u001b[0m\u001b[0m\n\u001b[0;32m-> 1187\u001b[0;31m         \u001b[0mhandler\u001b[0m \u001b[0;34m=\u001b[0m \u001b[0mgetattr\u001b[0m\u001b[0;34m(\u001b[0m\u001b[0mself\u001b[0m\u001b[0;34m,\u001b[0m \u001b[0;34m'handle_'\u001b[0m \u001b[0;34m+\u001b[0m \u001b[0mname\u001b[0m\u001b[0;34m,\u001b[0m \u001b[0;32mNone\u001b[0m\u001b[0;34m)\u001b[0m\u001b[0;34m\u001b[0m\u001b[0;34m\u001b[0m\u001b[0m\n\u001b[0m\u001b[1;32m   1188\u001b[0m         \u001b[0;32mif\u001b[0m \u001b[0mhandler\u001b[0m\u001b[0;34m:\u001b[0m\u001b[0;34m\u001b[0m\u001b[0;34m\u001b[0m\u001b[0m\n",
      "\u001b[0;31mSystemError\u001b[0m: <built-in function getattr> returned a result with an error set",
      "\nThe above exception was the direct cause of the following exception:\n",
      "\u001b[0;31mSystemError\u001b[0m                               Traceback (most recent call last)",
      "\u001b[0;32m~/ML_TERM/gym-micropolis-ga/micropolis/MicropolisCore/src/pyMicropolis/micropolisEngine/micropolisgenericengine.py\u001b[0m in \u001b[0;36minvokeCallback\u001b[0;34m(self, micropolis, name, *args)\u001b[0m\n\u001b[1;32m   1186\u001b[0m         \u001b[0;31m# In this case, micropolis is the same as self, so ignore it.\u001b[0m\u001b[0;34m\u001b[0m\u001b[0;34m\u001b[0m\u001b[0;34m\u001b[0m\u001b[0m\n\u001b[0;32m-> 1187\u001b[0;31m         \u001b[0mhandler\u001b[0m \u001b[0;34m=\u001b[0m \u001b[0mgetattr\u001b[0m\u001b[0;34m(\u001b[0m\u001b[0mself\u001b[0m\u001b[0;34m,\u001b[0m \u001b[0;34m'handle_'\u001b[0m \u001b[0;34m+\u001b[0m \u001b[0mname\u001b[0m\u001b[0;34m,\u001b[0m \u001b[0;32mNone\u001b[0m\u001b[0;34m)\u001b[0m\u001b[0;34m\u001b[0m\u001b[0;34m\u001b[0m\u001b[0m\n\u001b[0m\u001b[1;32m   1188\u001b[0m         \u001b[0;32mif\u001b[0m \u001b[0mhandler\u001b[0m\u001b[0;34m:\u001b[0m\u001b[0;34m\u001b[0m\u001b[0;34m\u001b[0m\u001b[0m\n",
      "\u001b[0;31mSystemError\u001b[0m: <built-in function getattr> returned a result with an error set",
      "\nThe above exception was the direct cause of the following exception:\n",
      "\u001b[0;31mSystemError\u001b[0m                               Traceback (most recent call last)",
      "\u001b[0;32m~/ML_TERM/gym-micropolis-ga/micropolis/MicropolisCore/src/pyMicropolis/micropolisEngine/micropolisgenericengine.py\u001b[0m in \u001b[0;36minvokeCallback\u001b[0;34m(self, micropolis, name, *args)\u001b[0m\n\u001b[1;32m   1186\u001b[0m         \u001b[0;31m# In this case, micropolis is the same as self, so ignore it.\u001b[0m\u001b[0;34m\u001b[0m\u001b[0;34m\u001b[0m\u001b[0;34m\u001b[0m\u001b[0m\n\u001b[0;32m-> 1187\u001b[0;31m         \u001b[0mhandler\u001b[0m \u001b[0;34m=\u001b[0m \u001b[0mgetattr\u001b[0m\u001b[0;34m(\u001b[0m\u001b[0mself\u001b[0m\u001b[0;34m,\u001b[0m \u001b[0;34m'handle_'\u001b[0m \u001b[0;34m+\u001b[0m \u001b[0mname\u001b[0m\u001b[0;34m,\u001b[0m \u001b[0;32mNone\u001b[0m\u001b[0;34m)\u001b[0m\u001b[0;34m\u001b[0m\u001b[0;34m\u001b[0m\u001b[0m\n\u001b[0m\u001b[1;32m   1188\u001b[0m         \u001b[0;32mif\u001b[0m \u001b[0mhandler\u001b[0m\u001b[0;34m:\u001b[0m\u001b[0;34m\u001b[0m\u001b[0;34m\u001b[0m\u001b[0m\n",
      "\u001b[0;31mSystemError\u001b[0m: <built-in function getattr> returned a result with an error set",
      "\nThe above exception was the direct cause of the following exception:\n",
      "\u001b[0;31mSystemError\u001b[0m                               Traceback (most recent call last)",
      "\u001b[0;32m~/ML_TERM/gym-micropolis-ga/micropolis/MicropolisCore/src/pyMicropolis/micropolisEngine/micropolisgenericengine.py\u001b[0m in \u001b[0;36minvokeCallback\u001b[0;34m(self, micropolis, name, *args)\u001b[0m\n\u001b[1;32m   1186\u001b[0m         \u001b[0;31m# In this case, micropolis is the same as self, so ignore it.\u001b[0m\u001b[0;34m\u001b[0m\u001b[0;34m\u001b[0m\u001b[0;34m\u001b[0m\u001b[0m\n\u001b[0;32m-> 1187\u001b[0;31m         \u001b[0mhandler\u001b[0m \u001b[0;34m=\u001b[0m \u001b[0mgetattr\u001b[0m\u001b[0;34m(\u001b[0m\u001b[0mself\u001b[0m\u001b[0;34m,\u001b[0m \u001b[0;34m'handle_'\u001b[0m \u001b[0;34m+\u001b[0m \u001b[0mname\u001b[0m\u001b[0;34m,\u001b[0m \u001b[0;32mNone\u001b[0m\u001b[0;34m)\u001b[0m\u001b[0;34m\u001b[0m\u001b[0;34m\u001b[0m\u001b[0m\n\u001b[0m\u001b[1;32m   1188\u001b[0m         \u001b[0;32mif\u001b[0m \u001b[0mhandler\u001b[0m\u001b[0;34m:\u001b[0m\u001b[0;34m\u001b[0m\u001b[0;34m\u001b[0m\u001b[0m\n",
      "\u001b[0;31mSystemError\u001b[0m: <built-in function getattr> returned a result with an error set",
      "\nThe above exception was the direct cause of the following exception:\n",
      "\u001b[0;31mSystemError\u001b[0m                               Traceback (most recent call last)",
      "\u001b[0;32m~/ML_TERM/gym-micropolis-ga/micropolis/MicropolisCore/src/pyMicropolis/micropolisEngine/micropolisgenericengine.py\u001b[0m in \u001b[0;36minvokeCallback\u001b[0;34m(self, micropolis, name, *args)\u001b[0m\n\u001b[1;32m   1186\u001b[0m         \u001b[0;31m# In this case, micropolis is the same as self, so ignore it.\u001b[0m\u001b[0;34m\u001b[0m\u001b[0;34m\u001b[0m\u001b[0;34m\u001b[0m\u001b[0m\n\u001b[0;32m-> 1187\u001b[0;31m         \u001b[0mhandler\u001b[0m \u001b[0;34m=\u001b[0m \u001b[0mgetattr\u001b[0m\u001b[0;34m(\u001b[0m\u001b[0mself\u001b[0m\u001b[0;34m,\u001b[0m \u001b[0;34m'handle_'\u001b[0m \u001b[0;34m+\u001b[0m \u001b[0mname\u001b[0m\u001b[0;34m,\u001b[0m \u001b[0;32mNone\u001b[0m\u001b[0;34m)\u001b[0m\u001b[0;34m\u001b[0m\u001b[0;34m\u001b[0m\u001b[0m\n\u001b[0m\u001b[1;32m   1188\u001b[0m         \u001b[0;32mif\u001b[0m \u001b[0mhandler\u001b[0m\u001b[0;34m:\u001b[0m\u001b[0;34m\u001b[0m\u001b[0;34m\u001b[0m\u001b[0m\n",
      "\u001b[0;31mSystemError\u001b[0m: <built-in function getattr> returned a result with an error set",
      "\nThe above exception was the direct cause of the following exception:\n",
      "\u001b[0;31mSystemError\u001b[0m                               Traceback (most recent call last)",
      "\u001b[0;32m~/ML_TERM/gym-micropolis-ga/micropolis/MicropolisCore/src/pyMicropolis/micropolisEngine/micropolisgenericengine.py\u001b[0m in \u001b[0;36minvokeCallback\u001b[0;34m(self, micropolis, name, *args)\u001b[0m\n\u001b[1;32m   1186\u001b[0m         \u001b[0;31m# In this case, micropolis is the same as self, so ignore it.\u001b[0m\u001b[0;34m\u001b[0m\u001b[0;34m\u001b[0m\u001b[0;34m\u001b[0m\u001b[0m\n\u001b[0;32m-> 1187\u001b[0;31m         \u001b[0mhandler\u001b[0m \u001b[0;34m=\u001b[0m \u001b[0mgetattr\u001b[0m\u001b[0;34m(\u001b[0m\u001b[0mself\u001b[0m\u001b[0;34m,\u001b[0m \u001b[0;34m'handle_'\u001b[0m \u001b[0;34m+\u001b[0m \u001b[0mname\u001b[0m\u001b[0;34m,\u001b[0m \u001b[0;32mNone\u001b[0m\u001b[0;34m)\u001b[0m\u001b[0;34m\u001b[0m\u001b[0;34m\u001b[0m\u001b[0m\n\u001b[0m\u001b[1;32m   1188\u001b[0m         \u001b[0;32mif\u001b[0m \u001b[0mhandler\u001b[0m\u001b[0;34m:\u001b[0m\u001b[0;34m\u001b[0m\u001b[0;34m\u001b[0m\u001b[0m\n",
      "\u001b[0;31mSystemError\u001b[0m: <built-in function getattr> returned a result with an error set",
      "\nThe above exception was the direct cause of the following exception:\n",
      "\u001b[0;31mSystemError\u001b[0m                               Traceback (most recent call last)",
      "\u001b[0;32m~/ML_TERM/gym-micropolis-ga/micropolis/MicropolisCore/src/pyMicropolis/micropolisEngine/micropolisgenericengine.py\u001b[0m in \u001b[0;36minvokeCallback\u001b[0;34m(self, micropolis, name, *args)\u001b[0m\n\u001b[1;32m   1186\u001b[0m         \u001b[0;31m# In this case, micropolis is the same as self, so ignore it.\u001b[0m\u001b[0;34m\u001b[0m\u001b[0;34m\u001b[0m\u001b[0;34m\u001b[0m\u001b[0m\n\u001b[0;32m-> 1187\u001b[0;31m         \u001b[0mhandler\u001b[0m \u001b[0;34m=\u001b[0m \u001b[0mgetattr\u001b[0m\u001b[0;34m(\u001b[0m\u001b[0mself\u001b[0m\u001b[0;34m,\u001b[0m \u001b[0;34m'handle_'\u001b[0m \u001b[0;34m+\u001b[0m \u001b[0mname\u001b[0m\u001b[0;34m,\u001b[0m \u001b[0;32mNone\u001b[0m\u001b[0;34m)\u001b[0m\u001b[0;34m\u001b[0m\u001b[0;34m\u001b[0m\u001b[0m\n\u001b[0m\u001b[1;32m   1188\u001b[0m         \u001b[0;32mif\u001b[0m \u001b[0mhandler\u001b[0m\u001b[0;34m:\u001b[0m\u001b[0;34m\u001b[0m\u001b[0;34m\u001b[0m\u001b[0m\n",
      "\u001b[0;31mSystemError\u001b[0m: <built-in function getattr> returned a result with an error set",
      "\nThe above exception was the direct cause of the following exception:\n",
      "\u001b[0;31mSystemError\u001b[0m                               Traceback (most recent call last)",
      "\u001b[0;32m~/ML_TERM/gym-micropolis-ga/micropolis/MicropolisCore/src/pyMicropolis/micropolisEngine/micropolisgenericengine.py\u001b[0m in \u001b[0;36minvokeCallback\u001b[0;34m(self, micropolis, name, *args)\u001b[0m\n\u001b[1;32m   1186\u001b[0m         \u001b[0;31m# In this case, micropolis is the same as self, so ignore it.\u001b[0m\u001b[0;34m\u001b[0m\u001b[0;34m\u001b[0m\u001b[0;34m\u001b[0m\u001b[0m\n\u001b[0;32m-> 1187\u001b[0;31m         \u001b[0mhandler\u001b[0m \u001b[0;34m=\u001b[0m \u001b[0mgetattr\u001b[0m\u001b[0;34m(\u001b[0m\u001b[0mself\u001b[0m\u001b[0;34m,\u001b[0m \u001b[0;34m'handle_'\u001b[0m \u001b[0;34m+\u001b[0m \u001b[0mname\u001b[0m\u001b[0;34m,\u001b[0m \u001b[0;32mNone\u001b[0m\u001b[0;34m)\u001b[0m\u001b[0;34m\u001b[0m\u001b[0;34m\u001b[0m\u001b[0m\n\u001b[0m\u001b[1;32m   1188\u001b[0m         \u001b[0;32mif\u001b[0m \u001b[0mhandler\u001b[0m\u001b[0;34m:\u001b[0m\u001b[0;34m\u001b[0m\u001b[0;34m\u001b[0m\u001b[0m\n",
      "\u001b[0;31mSystemError\u001b[0m: <built-in function getattr> returned a result with an error set",
      "\nThe above exception was the direct cause of the following exception:\n",
      "\u001b[0;31mSystemError\u001b[0m                               Traceback (most recent call last)",
      "\u001b[0;32m~/ML_TERM/gym-micropolis-ga/micropolis/MicropolisCore/src/pyMicropolis/micropolisEngine/micropolisgenericengine.py\u001b[0m in \u001b[0;36minvokeCallback\u001b[0;34m(self, micropolis, name, *args)\u001b[0m\n\u001b[1;32m   1186\u001b[0m         \u001b[0;31m# In this case, micropolis is the same as self, so ignore it.\u001b[0m\u001b[0;34m\u001b[0m\u001b[0;34m\u001b[0m\u001b[0;34m\u001b[0m\u001b[0m\n\u001b[0;32m-> 1187\u001b[0;31m         \u001b[0mhandler\u001b[0m \u001b[0;34m=\u001b[0m \u001b[0mgetattr\u001b[0m\u001b[0;34m(\u001b[0m\u001b[0mself\u001b[0m\u001b[0;34m,\u001b[0m \u001b[0;34m'handle_'\u001b[0m \u001b[0;34m+\u001b[0m \u001b[0mname\u001b[0m\u001b[0;34m,\u001b[0m \u001b[0;32mNone\u001b[0m\u001b[0;34m)\u001b[0m\u001b[0;34m\u001b[0m\u001b[0;34m\u001b[0m\u001b[0m\n\u001b[0m\u001b[1;32m   1188\u001b[0m         \u001b[0;32mif\u001b[0m \u001b[0mhandler\u001b[0m\u001b[0;34m:\u001b[0m\u001b[0;34m\u001b[0m\u001b[0;34m\u001b[0m\u001b[0m\n",
      "\u001b[0;31mSystemError\u001b[0m: <built-in function getattr> returned a result with an error set",
      "\nThe above exception was the direct cause of the following exception:\n",
      "\u001b[0;31mSystemError\u001b[0m                               Traceback (most recent call last)",
      "\u001b[0;32m~/ML_TERM/gym-micropolis-ga/micropolis/MicropolisCore/src/pyMicropolis/micropolisEngine/micropolisgenericengine.py\u001b[0m in \u001b[0;36minvokeCallback\u001b[0;34m(self, micropolis, name, *args)\u001b[0m\n\u001b[1;32m   1186\u001b[0m         \u001b[0;31m# In this case, micropolis is the same as self, so ignore it.\u001b[0m\u001b[0;34m\u001b[0m\u001b[0;34m\u001b[0m\u001b[0;34m\u001b[0m\u001b[0m\n\u001b[0;32m-> 1187\u001b[0;31m         \u001b[0mhandler\u001b[0m \u001b[0;34m=\u001b[0m \u001b[0mgetattr\u001b[0m\u001b[0;34m(\u001b[0m\u001b[0mself\u001b[0m\u001b[0;34m,\u001b[0m \u001b[0;34m'handle_'\u001b[0m \u001b[0;34m+\u001b[0m \u001b[0mname\u001b[0m\u001b[0;34m,\u001b[0m \u001b[0;32mNone\u001b[0m\u001b[0;34m)\u001b[0m\u001b[0;34m\u001b[0m\u001b[0;34m\u001b[0m\u001b[0m\n\u001b[0m\u001b[1;32m   1188\u001b[0m         \u001b[0;32mif\u001b[0m \u001b[0mhandler\u001b[0m\u001b[0;34m:\u001b[0m\u001b[0;34m\u001b[0m\u001b[0;34m\u001b[0m\u001b[0m\n",
      "\u001b[0;31mSystemError\u001b[0m: <built-in function getattr> returned a result with an error set",
      "\nThe above exception was the direct cause of the following exception:\n",
      "\u001b[0;31mSystemError\u001b[0m                               Traceback (most recent call last)",
      "\u001b[0;32m~/ML_TERM/gym-micropolis-ga/micropolis/MicropolisCore/src/pyMicropolis/micropolisEngine/micropolisgenericengine.py\u001b[0m in \u001b[0;36minvokeCallback\u001b[0;34m(self, micropolis, name, *args)\u001b[0m\n\u001b[1;32m   1186\u001b[0m         \u001b[0;31m# In this case, micropolis is the same as self, so ignore it.\u001b[0m\u001b[0;34m\u001b[0m\u001b[0;34m\u001b[0m\u001b[0;34m\u001b[0m\u001b[0m\n\u001b[0;32m-> 1187\u001b[0;31m         \u001b[0mhandler\u001b[0m \u001b[0;34m=\u001b[0m \u001b[0mgetattr\u001b[0m\u001b[0;34m(\u001b[0m\u001b[0mself\u001b[0m\u001b[0;34m,\u001b[0m \u001b[0;34m'handle_'\u001b[0m \u001b[0;34m+\u001b[0m \u001b[0mname\u001b[0m\u001b[0;34m,\u001b[0m \u001b[0;32mNone\u001b[0m\u001b[0;34m)\u001b[0m\u001b[0;34m\u001b[0m\u001b[0;34m\u001b[0m\u001b[0m\n\u001b[0m\u001b[1;32m   1188\u001b[0m         \u001b[0;32mif\u001b[0m \u001b[0mhandler\u001b[0m\u001b[0;34m:\u001b[0m\u001b[0;34m\u001b[0m\u001b[0;34m\u001b[0m\u001b[0m\n",
      "\u001b[0;31mSystemError\u001b[0m: <built-in function getattr> returned a result with an error set",
      "\nThe above exception was the direct cause of the following exception:\n",
      "\u001b[0;31mSystemError\u001b[0m                               Traceback (most recent call last)",
      "\u001b[0;32m~/ML_TERM/gym-micropolis-ga/micropolis/MicropolisCore/src/pyMicropolis/micropolisEngine/micropolisgenericengine.py\u001b[0m in \u001b[0;36minvokeCallback\u001b[0;34m(self, micropolis, name, *args)\u001b[0m\n\u001b[1;32m   1186\u001b[0m         \u001b[0;31m# In this case, micropolis is the same as self, so ignore it.\u001b[0m\u001b[0;34m\u001b[0m\u001b[0;34m\u001b[0m\u001b[0;34m\u001b[0m\u001b[0m\n\u001b[0;32m-> 1187\u001b[0;31m         \u001b[0mhandler\u001b[0m \u001b[0;34m=\u001b[0m \u001b[0mgetattr\u001b[0m\u001b[0;34m(\u001b[0m\u001b[0mself\u001b[0m\u001b[0;34m,\u001b[0m \u001b[0;34m'handle_'\u001b[0m \u001b[0;34m+\u001b[0m \u001b[0mname\u001b[0m\u001b[0;34m,\u001b[0m \u001b[0;32mNone\u001b[0m\u001b[0;34m)\u001b[0m\u001b[0;34m\u001b[0m\u001b[0;34m\u001b[0m\u001b[0m\n\u001b[0m\u001b[1;32m   1188\u001b[0m         \u001b[0;32mif\u001b[0m \u001b[0mhandler\u001b[0m\u001b[0;34m:\u001b[0m\u001b[0;34m\u001b[0m\u001b[0;34m\u001b[0m\u001b[0m\n",
      "\u001b[0;31mSystemError\u001b[0m: <built-in function getattr> returned a result with an error set",
      "\nThe above exception was the direct cause of the following exception:\n",
      "\u001b[0;31mSystemError\u001b[0m                               Traceback (most recent call last)",
      "\u001b[0;32m~/ML_TERM/gym-micropolis-ga/micropolis/MicropolisCore/src/pyMicropolis/micropolisEngine/micropolisgenericengine.py\u001b[0m in \u001b[0;36minvokeCallback\u001b[0;34m(self, micropolis, name, *args)\u001b[0m\n\u001b[1;32m   1186\u001b[0m         \u001b[0;31m# In this case, micropolis is the same as self, so ignore it.\u001b[0m\u001b[0;34m\u001b[0m\u001b[0;34m\u001b[0m\u001b[0;34m\u001b[0m\u001b[0m\n\u001b[0;32m-> 1187\u001b[0;31m         \u001b[0mhandler\u001b[0m \u001b[0;34m=\u001b[0m \u001b[0mgetattr\u001b[0m\u001b[0;34m(\u001b[0m\u001b[0mself\u001b[0m\u001b[0;34m,\u001b[0m \u001b[0;34m'handle_'\u001b[0m \u001b[0;34m+\u001b[0m \u001b[0mname\u001b[0m\u001b[0;34m,\u001b[0m \u001b[0;32mNone\u001b[0m\u001b[0;34m)\u001b[0m\u001b[0;34m\u001b[0m\u001b[0;34m\u001b[0m\u001b[0m\n\u001b[0m\u001b[1;32m   1188\u001b[0m         \u001b[0;32mif\u001b[0m \u001b[0mhandler\u001b[0m\u001b[0;34m:\u001b[0m\u001b[0;34m\u001b[0m\u001b[0;34m\u001b[0m\u001b[0m\n",
      "\u001b[0;31mSystemError\u001b[0m: <built-in function getattr> returned a result with an error set",
      "\nThe above exception was the direct cause of the following exception:\n",
      "\u001b[0;31mSystemError\u001b[0m                               Traceback (most recent call last)",
      "\u001b[0;32m~/ML_TERM/gym-micropolis-ga/micropolis/MicropolisCore/src/pyMicropolis/micropolisEngine/micropolisgenericengine.py\u001b[0m in \u001b[0;36minvokeCallback\u001b[0;34m(self, micropolis, name, *args)\u001b[0m\n\u001b[1;32m   1186\u001b[0m         \u001b[0;31m# In this case, micropolis is the same as self, so ignore it.\u001b[0m\u001b[0;34m\u001b[0m\u001b[0;34m\u001b[0m\u001b[0;34m\u001b[0m\u001b[0m\n\u001b[0;32m-> 1187\u001b[0;31m         \u001b[0mhandler\u001b[0m \u001b[0;34m=\u001b[0m \u001b[0mgetattr\u001b[0m\u001b[0;34m(\u001b[0m\u001b[0mself\u001b[0m\u001b[0;34m,\u001b[0m \u001b[0;34m'handle_'\u001b[0m \u001b[0;34m+\u001b[0m \u001b[0mname\u001b[0m\u001b[0;34m,\u001b[0m \u001b[0;32mNone\u001b[0m\u001b[0;34m)\u001b[0m\u001b[0;34m\u001b[0m\u001b[0;34m\u001b[0m\u001b[0m\n\u001b[0m\u001b[1;32m   1188\u001b[0m         \u001b[0;32mif\u001b[0m \u001b[0mhandler\u001b[0m\u001b[0;34m:\u001b[0m\u001b[0;34m\u001b[0m\u001b[0;34m\u001b[0m\u001b[0m\n",
      "\u001b[0;31mSystemError\u001b[0m: <built-in function getattr> returned a result with an error set",
      "\nThe above exception was the direct cause of the following exception:\n",
      "\u001b[0;31mSystemError\u001b[0m                               Traceback (most recent call last)",
      "\u001b[0;32m~/ML_TERM/gym-micropolis-ga/micropolis/MicropolisCore/src/pyMicropolis/micropolisEngine/micropolisgenericengine.py\u001b[0m in \u001b[0;36minvokeCallback\u001b[0;34m(self, micropolis, name, *args)\u001b[0m\n\u001b[1;32m   1186\u001b[0m         \u001b[0;31m# In this case, micropolis is the same as self, so ignore it.\u001b[0m\u001b[0;34m\u001b[0m\u001b[0;34m\u001b[0m\u001b[0;34m\u001b[0m\u001b[0m\n\u001b[0;32m-> 1187\u001b[0;31m         \u001b[0mhandler\u001b[0m \u001b[0;34m=\u001b[0m \u001b[0mgetattr\u001b[0m\u001b[0;34m(\u001b[0m\u001b[0mself\u001b[0m\u001b[0;34m,\u001b[0m \u001b[0;34m'handle_'\u001b[0m \u001b[0;34m+\u001b[0m \u001b[0mname\u001b[0m\u001b[0;34m,\u001b[0m \u001b[0;32mNone\u001b[0m\u001b[0;34m)\u001b[0m\u001b[0;34m\u001b[0m\u001b[0;34m\u001b[0m\u001b[0m\n\u001b[0m\u001b[1;32m   1188\u001b[0m         \u001b[0;32mif\u001b[0m \u001b[0mhandler\u001b[0m\u001b[0;34m:\u001b[0m\u001b[0;34m\u001b[0m\u001b[0;34m\u001b[0m\u001b[0m\n",
      "\u001b[0;31mSystemError\u001b[0m: <built-in function getattr> returned a result with an error set",
      "\nThe above exception was the direct cause of the following exception:\n",
      "\u001b[0;31mSystemError\u001b[0m                               Traceback (most recent call last)",
      "\u001b[0;32m~/ML_TERM/gym-micropolis-ga/micropolis/MicropolisCore/src/pyMicropolis/micropolisEngine/micropolisgenericengine.py\u001b[0m in \u001b[0;36minvokeCallback\u001b[0;34m(self, micropolis, name, *args)\u001b[0m\n\u001b[1;32m   1186\u001b[0m         \u001b[0;31m# In this case, micropolis is the same as self, so ignore it.\u001b[0m\u001b[0;34m\u001b[0m\u001b[0;34m\u001b[0m\u001b[0;34m\u001b[0m\u001b[0m\n\u001b[0;32m-> 1187\u001b[0;31m         \u001b[0mhandler\u001b[0m \u001b[0;34m=\u001b[0m \u001b[0mgetattr\u001b[0m\u001b[0;34m(\u001b[0m\u001b[0mself\u001b[0m\u001b[0;34m,\u001b[0m \u001b[0;34m'handle_'\u001b[0m \u001b[0;34m+\u001b[0m \u001b[0mname\u001b[0m\u001b[0;34m,\u001b[0m \u001b[0;32mNone\u001b[0m\u001b[0;34m)\u001b[0m\u001b[0;34m\u001b[0m\u001b[0;34m\u001b[0m\u001b[0m\n\u001b[0m\u001b[1;32m   1188\u001b[0m         \u001b[0;32mif\u001b[0m \u001b[0mhandler\u001b[0m\u001b[0;34m:\u001b[0m\u001b[0;34m\u001b[0m\u001b[0;34m\u001b[0m\u001b[0m\n",
      "\u001b[0;31mSystemError\u001b[0m: <built-in function getattr> returned a result with an error set",
      "\nThe above exception was the direct cause of the following exception:\n",
      "\u001b[0;31mSystemError\u001b[0m                               Traceback (most recent call last)",
      "\u001b[0;32m~/ML_TERM/gym-micropolis-ga/micropolis/MicropolisCore/src/pyMicropolis/micropolisEngine/micropolisgenericengine.py\u001b[0m in \u001b[0;36minvokeCallback\u001b[0;34m(self, micropolis, name, *args)\u001b[0m\n\u001b[1;32m   1186\u001b[0m         \u001b[0;31m# In this case, micropolis is the same as self, so ignore it.\u001b[0m\u001b[0;34m\u001b[0m\u001b[0;34m\u001b[0m\u001b[0;34m\u001b[0m\u001b[0m\n\u001b[0;32m-> 1187\u001b[0;31m         \u001b[0mhandler\u001b[0m \u001b[0;34m=\u001b[0m \u001b[0mgetattr\u001b[0m\u001b[0;34m(\u001b[0m\u001b[0mself\u001b[0m\u001b[0;34m,\u001b[0m \u001b[0;34m'handle_'\u001b[0m \u001b[0;34m+\u001b[0m \u001b[0mname\u001b[0m\u001b[0;34m,\u001b[0m \u001b[0;32mNone\u001b[0m\u001b[0;34m)\u001b[0m\u001b[0;34m\u001b[0m\u001b[0;34m\u001b[0m\u001b[0m\n\u001b[0m\u001b[1;32m   1188\u001b[0m         \u001b[0;32mif\u001b[0m \u001b[0mhandler\u001b[0m\u001b[0;34m:\u001b[0m\u001b[0;34m\u001b[0m\u001b[0;34m\u001b[0m\u001b[0m\n",
      "\u001b[0;31mSystemError\u001b[0m: <built-in function getattr> returned a result with an error set",
      "\nThe above exception was the direct cause of the following exception:\n",
      "\u001b[0;31mSystemError\u001b[0m                               Traceback (most recent call last)",
      "\u001b[0;32m~/ML_TERM/gym-micropolis-ga/micropolis/MicropolisCore/src/pyMicropolis/micropolisEngine/micropolisgenericengine.py\u001b[0m in \u001b[0;36minvokeCallback\u001b[0;34m(self, micropolis, name, *args)\u001b[0m\n\u001b[1;32m   1186\u001b[0m         \u001b[0;31m# In this case, micropolis is the same as self, so ignore it.\u001b[0m\u001b[0;34m\u001b[0m\u001b[0;34m\u001b[0m\u001b[0;34m\u001b[0m\u001b[0m\n\u001b[0;32m-> 1187\u001b[0;31m         \u001b[0mhandler\u001b[0m \u001b[0;34m=\u001b[0m \u001b[0mgetattr\u001b[0m\u001b[0;34m(\u001b[0m\u001b[0mself\u001b[0m\u001b[0;34m,\u001b[0m \u001b[0;34m'handle_'\u001b[0m \u001b[0;34m+\u001b[0m \u001b[0mname\u001b[0m\u001b[0;34m,\u001b[0m \u001b[0;32mNone\u001b[0m\u001b[0;34m)\u001b[0m\u001b[0;34m\u001b[0m\u001b[0;34m\u001b[0m\u001b[0m\n\u001b[0m\u001b[1;32m   1188\u001b[0m         \u001b[0;32mif\u001b[0m \u001b[0mhandler\u001b[0m\u001b[0;34m:\u001b[0m\u001b[0;34m\u001b[0m\u001b[0;34m\u001b[0m\u001b[0m\n",
      "\u001b[0;31mSystemError\u001b[0m: <built-in function getattr> returned a result with an error set",
      "\nThe above exception was the direct cause of the following exception:\n",
      "\u001b[0;31mSystemError\u001b[0m                               Traceback (most recent call last)",
      "\u001b[0;32m~/ML_TERM/gym-micropolis-ga/micropolis/MicropolisCore/src/pyMicropolis/micropolisEngine/micropolisgenericengine.py\u001b[0m in \u001b[0;36minvokeCallback\u001b[0;34m(self, micropolis, name, *args)\u001b[0m\n\u001b[1;32m   1186\u001b[0m         \u001b[0;31m# In this case, micropolis is the same as self, so ignore it.\u001b[0m\u001b[0;34m\u001b[0m\u001b[0;34m\u001b[0m\u001b[0;34m\u001b[0m\u001b[0m\n\u001b[0;32m-> 1187\u001b[0;31m         \u001b[0mhandler\u001b[0m \u001b[0;34m=\u001b[0m \u001b[0mgetattr\u001b[0m\u001b[0;34m(\u001b[0m\u001b[0mself\u001b[0m\u001b[0;34m,\u001b[0m \u001b[0;34m'handle_'\u001b[0m \u001b[0;34m+\u001b[0m \u001b[0mname\u001b[0m\u001b[0;34m,\u001b[0m \u001b[0;32mNone\u001b[0m\u001b[0;34m)\u001b[0m\u001b[0;34m\u001b[0m\u001b[0;34m\u001b[0m\u001b[0m\n\u001b[0m\u001b[1;32m   1188\u001b[0m         \u001b[0;32mif\u001b[0m \u001b[0mhandler\u001b[0m\u001b[0;34m:\u001b[0m\u001b[0;34m\u001b[0m\u001b[0;34m\u001b[0m\u001b[0m\n",
      "\u001b[0;31mSystemError\u001b[0m: <built-in function getattr> returned a result with an error set",
      "\nThe above exception was the direct cause of the following exception:\n",
      "\u001b[0;31mSystemError\u001b[0m                               Traceback (most recent call last)",
      "\u001b[0;32m~/ML_TERM/gym-micropolis-ga/micropolis/MicropolisCore/src/pyMicropolis/micropolisEngine/micropolisgenericengine.py\u001b[0m in \u001b[0;36minvokeCallback\u001b[0;34m(self, micropolis, name, *args)\u001b[0m\n\u001b[1;32m   1186\u001b[0m         \u001b[0;31m# In this case, micropolis is the same as self, so ignore it.\u001b[0m\u001b[0;34m\u001b[0m\u001b[0;34m\u001b[0m\u001b[0;34m\u001b[0m\u001b[0m\n\u001b[0;32m-> 1187\u001b[0;31m         \u001b[0mhandler\u001b[0m \u001b[0;34m=\u001b[0m \u001b[0mgetattr\u001b[0m\u001b[0;34m(\u001b[0m\u001b[0mself\u001b[0m\u001b[0;34m,\u001b[0m \u001b[0;34m'handle_'\u001b[0m \u001b[0;34m+\u001b[0m \u001b[0mname\u001b[0m\u001b[0;34m,\u001b[0m \u001b[0;32mNone\u001b[0m\u001b[0;34m)\u001b[0m\u001b[0;34m\u001b[0m\u001b[0;34m\u001b[0m\u001b[0m\n\u001b[0m\u001b[1;32m   1188\u001b[0m         \u001b[0;32mif\u001b[0m \u001b[0mhandler\u001b[0m\u001b[0;34m:\u001b[0m\u001b[0;34m\u001b[0m\u001b[0;34m\u001b[0m\u001b[0m\n",
      "\u001b[0;31mSystemError\u001b[0m: <built-in function getattr> returned a result with an error set",
      "\nThe above exception was the direct cause of the following exception:\n",
      "\u001b[0;31mSystemError\u001b[0m                               Traceback (most recent call last)",
      "\u001b[0;32m~/ML_TERM/gym-micropolis-ga/micropolis/MicropolisCore/src/pyMicropolis/micropolisEngine/micropolisgenericengine.py\u001b[0m in \u001b[0;36minvokeCallback\u001b[0;34m(self, micropolis, name, *args)\u001b[0m\n\u001b[1;32m   1186\u001b[0m         \u001b[0;31m# In this case, micropolis is the same as self, so ignore it.\u001b[0m\u001b[0;34m\u001b[0m\u001b[0;34m\u001b[0m\u001b[0;34m\u001b[0m\u001b[0m\n\u001b[0;32m-> 1187\u001b[0;31m         \u001b[0mhandler\u001b[0m \u001b[0;34m=\u001b[0m \u001b[0mgetattr\u001b[0m\u001b[0;34m(\u001b[0m\u001b[0mself\u001b[0m\u001b[0;34m,\u001b[0m \u001b[0;34m'handle_'\u001b[0m \u001b[0;34m+\u001b[0m \u001b[0mname\u001b[0m\u001b[0;34m,\u001b[0m \u001b[0;32mNone\u001b[0m\u001b[0;34m)\u001b[0m\u001b[0;34m\u001b[0m\u001b[0;34m\u001b[0m\u001b[0m\n\u001b[0m\u001b[1;32m   1188\u001b[0m         \u001b[0;32mif\u001b[0m \u001b[0mhandler\u001b[0m\u001b[0;34m:\u001b[0m\u001b[0;34m\u001b[0m\u001b[0;34m\u001b[0m\u001b[0m\n",
      "\u001b[0;31mSystemError\u001b[0m: <built-in function getattr> returned a result with an error set",
      "\nThe above exception was the direct cause of the following exception:\n",
      "\u001b[0;31mSystemError\u001b[0m                               Traceback (most recent call last)",
      "\u001b[0;32m~/ML_TERM/gym-micropolis-ga/micropolis/MicropolisCore/src/pyMicropolis/micropolisEngine/micropolisgenericengine.py\u001b[0m in \u001b[0;36minvokeCallback\u001b[0;34m(self, micropolis, name, *args)\u001b[0m\n\u001b[1;32m   1186\u001b[0m         \u001b[0;31m# In this case, micropolis is the same as self, so ignore it.\u001b[0m\u001b[0;34m\u001b[0m\u001b[0;34m\u001b[0m\u001b[0;34m\u001b[0m\u001b[0m\n\u001b[0;32m-> 1187\u001b[0;31m         \u001b[0mhandler\u001b[0m \u001b[0;34m=\u001b[0m \u001b[0mgetattr\u001b[0m\u001b[0;34m(\u001b[0m\u001b[0mself\u001b[0m\u001b[0;34m,\u001b[0m \u001b[0;34m'handle_'\u001b[0m \u001b[0;34m+\u001b[0m \u001b[0mname\u001b[0m\u001b[0;34m,\u001b[0m \u001b[0;32mNone\u001b[0m\u001b[0;34m)\u001b[0m\u001b[0;34m\u001b[0m\u001b[0;34m\u001b[0m\u001b[0m\n\u001b[0m\u001b[1;32m   1188\u001b[0m         \u001b[0;32mif\u001b[0m \u001b[0mhandler\u001b[0m\u001b[0;34m:\u001b[0m\u001b[0;34m\u001b[0m\u001b[0;34m\u001b[0m\u001b[0m\n",
      "\u001b[0;31mSystemError\u001b[0m: <built-in function getattr> returned a result with an error set",
      "\nThe above exception was the direct cause of the following exception:\n",
      "\u001b[0;31mSystemError\u001b[0m                               Traceback (most recent call last)",
      "\u001b[0;32m~/ML_TERM/gym-micropolis-ga/micropolis/MicropolisCore/src/pyMicropolis/micropolisEngine/micropolisgenericengine.py\u001b[0m in \u001b[0;36minvokeCallback\u001b[0;34m(self, micropolis, name, *args)\u001b[0m\n\u001b[1;32m   1186\u001b[0m         \u001b[0;31m# In this case, micropolis is the same as self, so ignore it.\u001b[0m\u001b[0;34m\u001b[0m\u001b[0;34m\u001b[0m\u001b[0;34m\u001b[0m\u001b[0m\n\u001b[0;32m-> 1187\u001b[0;31m         \u001b[0mhandler\u001b[0m \u001b[0;34m=\u001b[0m \u001b[0mgetattr\u001b[0m\u001b[0;34m(\u001b[0m\u001b[0mself\u001b[0m\u001b[0;34m,\u001b[0m \u001b[0;34m'handle_'\u001b[0m \u001b[0;34m+\u001b[0m \u001b[0mname\u001b[0m\u001b[0;34m,\u001b[0m \u001b[0;32mNone\u001b[0m\u001b[0;34m)\u001b[0m\u001b[0;34m\u001b[0m\u001b[0;34m\u001b[0m\u001b[0m\n\u001b[0m\u001b[1;32m   1188\u001b[0m         \u001b[0;32mif\u001b[0m \u001b[0mhandler\u001b[0m\u001b[0;34m:\u001b[0m\u001b[0;34m\u001b[0m\u001b[0;34m\u001b[0m\u001b[0m\n",
      "\u001b[0;31mSystemError\u001b[0m: <built-in function getattr> returned a result with an error set",
      "\nThe above exception was the direct cause of the following exception:\n",
      "\u001b[0;31mSystemError\u001b[0m                               Traceback (most recent call last)",
      "\u001b[0;32m~/ML_TERM/gym-micropolis-ga/micropolis/MicropolisCore/src/pyMicropolis/micropolisEngine/micropolisgenericengine.py\u001b[0m in \u001b[0;36minvokeCallback\u001b[0;34m(self, micropolis, name, *args)\u001b[0m\n\u001b[1;32m   1186\u001b[0m         \u001b[0;31m# In this case, micropolis is the same as self, so ignore it.\u001b[0m\u001b[0;34m\u001b[0m\u001b[0;34m\u001b[0m\u001b[0;34m\u001b[0m\u001b[0m\n\u001b[0;32m-> 1187\u001b[0;31m         \u001b[0mhandler\u001b[0m \u001b[0;34m=\u001b[0m \u001b[0mgetattr\u001b[0m\u001b[0;34m(\u001b[0m\u001b[0mself\u001b[0m\u001b[0;34m,\u001b[0m \u001b[0;34m'handle_'\u001b[0m \u001b[0;34m+\u001b[0m \u001b[0mname\u001b[0m\u001b[0;34m,\u001b[0m \u001b[0;32mNone\u001b[0m\u001b[0;34m)\u001b[0m\u001b[0;34m\u001b[0m\u001b[0;34m\u001b[0m\u001b[0m\n\u001b[0m\u001b[1;32m   1188\u001b[0m         \u001b[0;32mif\u001b[0m \u001b[0mhandler\u001b[0m\u001b[0;34m:\u001b[0m\u001b[0;34m\u001b[0m\u001b[0;34m\u001b[0m\u001b[0m\n",
      "\u001b[0;31mSystemError\u001b[0m: <built-in function getattr> returned a result with an error set",
      "\nThe above exception was the direct cause of the following exception:\n",
      "\u001b[0;31mSystemError\u001b[0m                               Traceback (most recent call last)",
      "\u001b[0;32m~/ML_TERM/gym-micropolis-ga/micropolis/MicropolisCore/src/pyMicropolis/micropolisEngine/micropolisgenericengine.py\u001b[0m in \u001b[0;36minvokeCallback\u001b[0;34m(self, micropolis, name, *args)\u001b[0m\n\u001b[1;32m   1186\u001b[0m         \u001b[0;31m# In this case, micropolis is the same as self, so ignore it.\u001b[0m\u001b[0;34m\u001b[0m\u001b[0;34m\u001b[0m\u001b[0;34m\u001b[0m\u001b[0m\n\u001b[0;32m-> 1187\u001b[0;31m         \u001b[0mhandler\u001b[0m \u001b[0;34m=\u001b[0m \u001b[0mgetattr\u001b[0m\u001b[0;34m(\u001b[0m\u001b[0mself\u001b[0m\u001b[0;34m,\u001b[0m \u001b[0;34m'handle_'\u001b[0m \u001b[0;34m+\u001b[0m \u001b[0mname\u001b[0m\u001b[0;34m,\u001b[0m \u001b[0;32mNone\u001b[0m\u001b[0;34m)\u001b[0m\u001b[0;34m\u001b[0m\u001b[0;34m\u001b[0m\u001b[0m\n\u001b[0m\u001b[1;32m   1188\u001b[0m         \u001b[0;32mif\u001b[0m \u001b[0mhandler\u001b[0m\u001b[0;34m:\u001b[0m\u001b[0;34m\u001b[0m\u001b[0;34m\u001b[0m\u001b[0m\n",
      "\u001b[0;31mSystemError\u001b[0m: <built-in function getattr> returned a result with an error set",
      "\nThe above exception was the direct cause of the following exception:\n",
      "\u001b[0;31mSystemError\u001b[0m                               Traceback (most recent call last)",
      "\u001b[0;32m~/ML_TERM/gym-micropolis-ga/micropolis/MicropolisCore/src/pyMicropolis/micropolisEngine/micropolisgenericengine.py\u001b[0m in \u001b[0;36minvokeCallback\u001b[0;34m(self, micropolis, name, *args)\u001b[0m\n\u001b[1;32m   1186\u001b[0m         \u001b[0;31m# In this case, micropolis is the same as self, so ignore it.\u001b[0m\u001b[0;34m\u001b[0m\u001b[0;34m\u001b[0m\u001b[0;34m\u001b[0m\u001b[0m\n\u001b[0;32m-> 1187\u001b[0;31m         \u001b[0mhandler\u001b[0m \u001b[0;34m=\u001b[0m \u001b[0mgetattr\u001b[0m\u001b[0;34m(\u001b[0m\u001b[0mself\u001b[0m\u001b[0;34m,\u001b[0m \u001b[0;34m'handle_'\u001b[0m \u001b[0;34m+\u001b[0m \u001b[0mname\u001b[0m\u001b[0;34m,\u001b[0m \u001b[0;32mNone\u001b[0m\u001b[0;34m)\u001b[0m\u001b[0;34m\u001b[0m\u001b[0;34m\u001b[0m\u001b[0m\n\u001b[0m\u001b[1;32m   1188\u001b[0m         \u001b[0;32mif\u001b[0m \u001b[0mhandler\u001b[0m\u001b[0;34m:\u001b[0m\u001b[0;34m\u001b[0m\u001b[0;34m\u001b[0m\u001b[0m\n",
      "\u001b[0;31mSystemError\u001b[0m: <built-in function getattr> returned a result with an error set",
      "\nThe above exception was the direct cause of the following exception:\n",
      "\u001b[0;31mSystemError\u001b[0m                               Traceback (most recent call last)",
      "\u001b[0;32m~/ML_TERM/gym-micropolis-ga/micropolis/MicropolisCore/src/pyMicropolis/micropolisEngine/micropolisgenericengine.py\u001b[0m in \u001b[0;36minvokeCallback\u001b[0;34m(self, micropolis, name, *args)\u001b[0m\n\u001b[1;32m   1186\u001b[0m         \u001b[0;31m# In this case, micropolis is the same as self, so ignore it.\u001b[0m\u001b[0;34m\u001b[0m\u001b[0;34m\u001b[0m\u001b[0;34m\u001b[0m\u001b[0m\n\u001b[0;32m-> 1187\u001b[0;31m         \u001b[0mhandler\u001b[0m \u001b[0;34m=\u001b[0m \u001b[0mgetattr\u001b[0m\u001b[0;34m(\u001b[0m\u001b[0mself\u001b[0m\u001b[0;34m,\u001b[0m \u001b[0;34m'handle_'\u001b[0m \u001b[0;34m+\u001b[0m \u001b[0mname\u001b[0m\u001b[0;34m,\u001b[0m \u001b[0;32mNone\u001b[0m\u001b[0;34m)\u001b[0m\u001b[0;34m\u001b[0m\u001b[0;34m\u001b[0m\u001b[0m\n\u001b[0m\u001b[1;32m   1188\u001b[0m         \u001b[0;32mif\u001b[0m \u001b[0mhandler\u001b[0m\u001b[0;34m:\u001b[0m\u001b[0;34m\u001b[0m\u001b[0;34m\u001b[0m\u001b[0m\n",
      "\u001b[0;31mSystemError\u001b[0m: <built-in function getattr> returned a result with an error set",
      "\nThe above exception was the direct cause of the following exception:\n",
      "\u001b[0;31mSystemError\u001b[0m                               Traceback (most recent call last)",
      "\u001b[0;32m~/ML_TERM/gym-micropolis-ga/micropolis/MicropolisCore/src/pyMicropolis/micropolisEngine/micropolisgenericengine.py\u001b[0m in \u001b[0;36minvokeCallback\u001b[0;34m(self, micropolis, name, *args)\u001b[0m\n\u001b[1;32m   1186\u001b[0m         \u001b[0;31m# In this case, micropolis is the same as self, so ignore it.\u001b[0m\u001b[0;34m\u001b[0m\u001b[0;34m\u001b[0m\u001b[0;34m\u001b[0m\u001b[0m\n\u001b[0;32m-> 1187\u001b[0;31m         \u001b[0mhandler\u001b[0m \u001b[0;34m=\u001b[0m \u001b[0mgetattr\u001b[0m\u001b[0;34m(\u001b[0m\u001b[0mself\u001b[0m\u001b[0;34m,\u001b[0m \u001b[0;34m'handle_'\u001b[0m \u001b[0;34m+\u001b[0m \u001b[0mname\u001b[0m\u001b[0;34m,\u001b[0m \u001b[0;32mNone\u001b[0m\u001b[0;34m)\u001b[0m\u001b[0;34m\u001b[0m\u001b[0;34m\u001b[0m\u001b[0m\n\u001b[0m\u001b[1;32m   1188\u001b[0m         \u001b[0;32mif\u001b[0m \u001b[0mhandler\u001b[0m\u001b[0;34m:\u001b[0m\u001b[0;34m\u001b[0m\u001b[0;34m\u001b[0m\u001b[0m\n",
      "\u001b[0;31mSystemError\u001b[0m: <built-in function getattr> returned a result with an error set",
      "\nThe above exception was the direct cause of the following exception:\n",
      "\u001b[0;31mSystemError\u001b[0m                               Traceback (most recent call last)",
      "\u001b[0;32m~/ML_TERM/gym-micropolis-ga/micropolis/MicropolisCore/src/pyMicropolis/micropolisEngine/micropolisgenericengine.py\u001b[0m in \u001b[0;36minvokeCallback\u001b[0;34m(self, micropolis, name, *args)\u001b[0m\n\u001b[1;32m   1186\u001b[0m         \u001b[0;31m# In this case, micropolis is the same as self, so ignore it.\u001b[0m\u001b[0;34m\u001b[0m\u001b[0;34m\u001b[0m\u001b[0;34m\u001b[0m\u001b[0m\n\u001b[0;32m-> 1187\u001b[0;31m         \u001b[0mhandler\u001b[0m \u001b[0;34m=\u001b[0m \u001b[0mgetattr\u001b[0m\u001b[0;34m(\u001b[0m\u001b[0mself\u001b[0m\u001b[0;34m,\u001b[0m \u001b[0;34m'handle_'\u001b[0m \u001b[0;34m+\u001b[0m \u001b[0mname\u001b[0m\u001b[0;34m,\u001b[0m \u001b[0;32mNone\u001b[0m\u001b[0;34m)\u001b[0m\u001b[0;34m\u001b[0m\u001b[0;34m\u001b[0m\u001b[0m\n\u001b[0m\u001b[1;32m   1188\u001b[0m         \u001b[0;32mif\u001b[0m \u001b[0mhandler\u001b[0m\u001b[0;34m:\u001b[0m\u001b[0;34m\u001b[0m\u001b[0;34m\u001b[0m\u001b[0m\n",
      "\u001b[0;31mSystemError\u001b[0m: <built-in function getattr> returned a result with an error set",
      "\nThe above exception was the direct cause of the following exception:\n",
      "\u001b[0;31mSystemError\u001b[0m                               Traceback (most recent call last)",
      "\u001b[0;32m~/ML_TERM/gym-micropolis-ga/micropolis/MicropolisCore/src/pyMicropolis/micropolisEngine/micropolisgenericengine.py\u001b[0m in \u001b[0;36minvokeCallback\u001b[0;34m(self, micropolis, name, *args)\u001b[0m\n\u001b[1;32m   1186\u001b[0m         \u001b[0;31m# In this case, micropolis is the same as self, so ignore it.\u001b[0m\u001b[0;34m\u001b[0m\u001b[0;34m\u001b[0m\u001b[0;34m\u001b[0m\u001b[0m\n\u001b[0;32m-> 1187\u001b[0;31m         \u001b[0mhandler\u001b[0m \u001b[0;34m=\u001b[0m \u001b[0mgetattr\u001b[0m\u001b[0;34m(\u001b[0m\u001b[0mself\u001b[0m\u001b[0;34m,\u001b[0m \u001b[0;34m'handle_'\u001b[0m \u001b[0;34m+\u001b[0m \u001b[0mname\u001b[0m\u001b[0;34m,\u001b[0m \u001b[0;32mNone\u001b[0m\u001b[0;34m)\u001b[0m\u001b[0;34m\u001b[0m\u001b[0;34m\u001b[0m\u001b[0m\n\u001b[0m\u001b[1;32m   1188\u001b[0m         \u001b[0;32mif\u001b[0m \u001b[0mhandler\u001b[0m\u001b[0;34m:\u001b[0m\u001b[0;34m\u001b[0m\u001b[0;34m\u001b[0m\u001b[0m\n",
      "\u001b[0;31mSystemError\u001b[0m: <built-in function getattr> returned a result with an error set",
      "\nThe above exception was the direct cause of the following exception:\n",
      "\u001b[0;31mSystemError\u001b[0m                               Traceback (most recent call last)",
      "\u001b[0;32m~/ML_TERM/gym-micropolis-ga/micropolis/MicropolisCore/src/pyMicropolis/micropolisEngine/micropolisgenericengine.py\u001b[0m in \u001b[0;36minvokeCallback\u001b[0;34m(self, micropolis, name, *args)\u001b[0m\n\u001b[1;32m   1186\u001b[0m         \u001b[0;31m# In this case, micropolis is the same as self, so ignore it.\u001b[0m\u001b[0;34m\u001b[0m\u001b[0;34m\u001b[0m\u001b[0;34m\u001b[0m\u001b[0m\n\u001b[0;32m-> 1187\u001b[0;31m         \u001b[0mhandler\u001b[0m \u001b[0;34m=\u001b[0m \u001b[0mgetattr\u001b[0m\u001b[0;34m(\u001b[0m\u001b[0mself\u001b[0m\u001b[0;34m,\u001b[0m \u001b[0;34m'handle_'\u001b[0m \u001b[0;34m+\u001b[0m \u001b[0mname\u001b[0m\u001b[0;34m,\u001b[0m \u001b[0;32mNone\u001b[0m\u001b[0;34m)\u001b[0m\u001b[0;34m\u001b[0m\u001b[0;34m\u001b[0m\u001b[0m\n\u001b[0m\u001b[1;32m   1188\u001b[0m         \u001b[0;32mif\u001b[0m \u001b[0mhandler\u001b[0m\u001b[0;34m:\u001b[0m\u001b[0;34m\u001b[0m\u001b[0;34m\u001b[0m\u001b[0m\n",
      "\u001b[0;31mSystemError\u001b[0m: <built-in function getattr> returned a result with an error set",
      "\nThe above exception was the direct cause of the following exception:\n",
      "\u001b[0;31mSystemError\u001b[0m                               Traceback (most recent call last)",
      "\u001b[0;32m~/ML_TERM/gym-micropolis-ga/micropolis/MicropolisCore/src/pyMicropolis/micropolisEngine/micropolisgenericengine.py\u001b[0m in \u001b[0;36minvokeCallback\u001b[0;34m(self, micropolis, name, *args)\u001b[0m\n\u001b[1;32m   1186\u001b[0m         \u001b[0;31m# In this case, micropolis is the same as self, so ignore it.\u001b[0m\u001b[0;34m\u001b[0m\u001b[0;34m\u001b[0m\u001b[0;34m\u001b[0m\u001b[0m\n\u001b[0;32m-> 1187\u001b[0;31m         \u001b[0mhandler\u001b[0m \u001b[0;34m=\u001b[0m \u001b[0mgetattr\u001b[0m\u001b[0;34m(\u001b[0m\u001b[0mself\u001b[0m\u001b[0;34m,\u001b[0m \u001b[0;34m'handle_'\u001b[0m \u001b[0;34m+\u001b[0m \u001b[0mname\u001b[0m\u001b[0;34m,\u001b[0m \u001b[0;32mNone\u001b[0m\u001b[0;34m)\u001b[0m\u001b[0;34m\u001b[0m\u001b[0;34m\u001b[0m\u001b[0m\n\u001b[0m\u001b[1;32m   1188\u001b[0m         \u001b[0;32mif\u001b[0m \u001b[0mhandler\u001b[0m\u001b[0;34m:\u001b[0m\u001b[0;34m\u001b[0m\u001b[0;34m\u001b[0m\u001b[0m\n",
      "\u001b[0;31mSystemError\u001b[0m: <built-in function getattr> returned a result with an error set",
      "\nThe above exception was the direct cause of the following exception:\n",
      "\u001b[0;31mSystemError\u001b[0m                               Traceback (most recent call last)",
      "\u001b[0;32m~/ML_TERM/gym-micropolis-ga/micropolis/MicropolisCore/src/pyMicropolis/micropolisEngine/micropolisgenericengine.py\u001b[0m in \u001b[0;36minvokeCallback\u001b[0;34m(self, micropolis, name, *args)\u001b[0m\n\u001b[1;32m   1186\u001b[0m         \u001b[0;31m# In this case, micropolis is the same as self, so ignore it.\u001b[0m\u001b[0;34m\u001b[0m\u001b[0;34m\u001b[0m\u001b[0;34m\u001b[0m\u001b[0m\n\u001b[0;32m-> 1187\u001b[0;31m         \u001b[0mhandler\u001b[0m \u001b[0;34m=\u001b[0m \u001b[0mgetattr\u001b[0m\u001b[0;34m(\u001b[0m\u001b[0mself\u001b[0m\u001b[0;34m,\u001b[0m \u001b[0;34m'handle_'\u001b[0m \u001b[0;34m+\u001b[0m \u001b[0mname\u001b[0m\u001b[0;34m,\u001b[0m \u001b[0;32mNone\u001b[0m\u001b[0;34m)\u001b[0m\u001b[0;34m\u001b[0m\u001b[0;34m\u001b[0m\u001b[0m\n\u001b[0m\u001b[1;32m   1188\u001b[0m         \u001b[0;32mif\u001b[0m \u001b[0mhandler\u001b[0m\u001b[0;34m:\u001b[0m\u001b[0;34m\u001b[0m\u001b[0;34m\u001b[0m\u001b[0m\n",
      "\u001b[0;31mSystemError\u001b[0m: <built-in function getattr> returned a result with an error set",
      "\nThe above exception was the direct cause of the following exception:\n",
      "\u001b[0;31mSystemError\u001b[0m                               Traceback (most recent call last)",
      "\u001b[0;32m~/ML_TERM/gym-micropolis-ga/micropolis/MicropolisCore/src/pyMicropolis/micropolisEngine/micropolisgenericengine.py\u001b[0m in \u001b[0;36minvokeCallback\u001b[0;34m(self, micropolis, name, *args)\u001b[0m\n\u001b[1;32m   1186\u001b[0m         \u001b[0;31m# In this case, micropolis is the same as self, so ignore it.\u001b[0m\u001b[0;34m\u001b[0m\u001b[0;34m\u001b[0m\u001b[0;34m\u001b[0m\u001b[0m\n\u001b[0;32m-> 1187\u001b[0;31m         \u001b[0mhandler\u001b[0m \u001b[0;34m=\u001b[0m \u001b[0mgetattr\u001b[0m\u001b[0;34m(\u001b[0m\u001b[0mself\u001b[0m\u001b[0;34m,\u001b[0m \u001b[0;34m'handle_'\u001b[0m \u001b[0;34m+\u001b[0m \u001b[0mname\u001b[0m\u001b[0;34m,\u001b[0m \u001b[0;32mNone\u001b[0m\u001b[0;34m)\u001b[0m\u001b[0;34m\u001b[0m\u001b[0;34m\u001b[0m\u001b[0m\n\u001b[0m\u001b[1;32m   1188\u001b[0m         \u001b[0;32mif\u001b[0m \u001b[0mhandler\u001b[0m\u001b[0;34m:\u001b[0m\u001b[0;34m\u001b[0m\u001b[0;34m\u001b[0m\u001b[0m\n",
      "\u001b[0;31mSystemError\u001b[0m: <built-in function getattr> returned a result with an error set",
      "\nThe above exception was the direct cause of the following exception:\n",
      "\u001b[0;31mSystemError\u001b[0m                               Traceback (most recent call last)",
      "\u001b[0;32m~/ML_TERM/gym-micropolis-ga/micropolis/MicropolisCore/src/pyMicropolis/micropolisEngine/micropolisgenericengine.py\u001b[0m in \u001b[0;36minvokeCallback\u001b[0;34m(self, micropolis, name, *args)\u001b[0m\n\u001b[1;32m   1186\u001b[0m         \u001b[0;31m# In this case, micropolis is the same as self, so ignore it.\u001b[0m\u001b[0;34m\u001b[0m\u001b[0;34m\u001b[0m\u001b[0;34m\u001b[0m\u001b[0m\n\u001b[0;32m-> 1187\u001b[0;31m         \u001b[0mhandler\u001b[0m \u001b[0;34m=\u001b[0m \u001b[0mgetattr\u001b[0m\u001b[0;34m(\u001b[0m\u001b[0mself\u001b[0m\u001b[0;34m,\u001b[0m \u001b[0;34m'handle_'\u001b[0m \u001b[0;34m+\u001b[0m \u001b[0mname\u001b[0m\u001b[0;34m,\u001b[0m \u001b[0;32mNone\u001b[0m\u001b[0;34m)\u001b[0m\u001b[0;34m\u001b[0m\u001b[0;34m\u001b[0m\u001b[0m\n\u001b[0m\u001b[1;32m   1188\u001b[0m         \u001b[0;32mif\u001b[0m \u001b[0mhandler\u001b[0m\u001b[0;34m:\u001b[0m\u001b[0;34m\u001b[0m\u001b[0;34m\u001b[0m\u001b[0m\n",
      "\u001b[0;31mSystemError\u001b[0m: <built-in function getattr> returned a result with an error set",
      "\nThe above exception was the direct cause of the following exception:\n",
      "\u001b[0;31mSystemError\u001b[0m                               Traceback (most recent call last)",
      "\u001b[0;32m~/ML_TERM/gym-micropolis-ga/micropolis/MicropolisCore/src/pyMicropolis/micropolisEngine/micropolisgenericengine.py\u001b[0m in \u001b[0;36minvokeCallback\u001b[0;34m(self, micropolis, name, *args)\u001b[0m\n\u001b[1;32m   1186\u001b[0m         \u001b[0;31m# In this case, micropolis is the same as self, so ignore it.\u001b[0m\u001b[0;34m\u001b[0m\u001b[0;34m\u001b[0m\u001b[0;34m\u001b[0m\u001b[0m\n\u001b[0;32m-> 1187\u001b[0;31m         \u001b[0mhandler\u001b[0m \u001b[0;34m=\u001b[0m \u001b[0mgetattr\u001b[0m\u001b[0;34m(\u001b[0m\u001b[0mself\u001b[0m\u001b[0;34m,\u001b[0m \u001b[0;34m'handle_'\u001b[0m \u001b[0;34m+\u001b[0m \u001b[0mname\u001b[0m\u001b[0;34m,\u001b[0m \u001b[0;32mNone\u001b[0m\u001b[0;34m)\u001b[0m\u001b[0;34m\u001b[0m\u001b[0;34m\u001b[0m\u001b[0m\n\u001b[0m\u001b[1;32m   1188\u001b[0m         \u001b[0;32mif\u001b[0m \u001b[0mhandler\u001b[0m\u001b[0;34m:\u001b[0m\u001b[0;34m\u001b[0m\u001b[0;34m\u001b[0m\u001b[0m\n",
      "\u001b[0;31mSystemError\u001b[0m: <built-in function getattr> returned a result with an error set",
      "\nThe above exception was the direct cause of the following exception:\n",
      "\u001b[0;31mSystemError\u001b[0m                               Traceback (most recent call last)",
      "\u001b[0;32m~/ML_TERM/gym-micropolis-ga/micropolis/MicropolisCore/src/pyMicropolis/micropolisEngine/micropolisgenericengine.py\u001b[0m in \u001b[0;36minvokeCallback\u001b[0;34m(self, micropolis, name, *args)\u001b[0m\n\u001b[1;32m   1186\u001b[0m         \u001b[0;31m# In this case, micropolis is the same as self, so ignore it.\u001b[0m\u001b[0;34m\u001b[0m\u001b[0;34m\u001b[0m\u001b[0;34m\u001b[0m\u001b[0m\n\u001b[0;32m-> 1187\u001b[0;31m         \u001b[0mhandler\u001b[0m \u001b[0;34m=\u001b[0m \u001b[0mgetattr\u001b[0m\u001b[0;34m(\u001b[0m\u001b[0mself\u001b[0m\u001b[0;34m,\u001b[0m \u001b[0;34m'handle_'\u001b[0m \u001b[0;34m+\u001b[0m \u001b[0mname\u001b[0m\u001b[0;34m,\u001b[0m \u001b[0;32mNone\u001b[0m\u001b[0;34m)\u001b[0m\u001b[0;34m\u001b[0m\u001b[0;34m\u001b[0m\u001b[0m\n\u001b[0m\u001b[1;32m   1188\u001b[0m         \u001b[0;32mif\u001b[0m \u001b[0mhandler\u001b[0m\u001b[0;34m:\u001b[0m\u001b[0;34m\u001b[0m\u001b[0;34m\u001b[0m\u001b[0m\n",
      "\u001b[0;31mSystemError\u001b[0m: <built-in function getattr> returned a result with an error set",
      "\nThe above exception was the direct cause of the following exception:\n",
      "\u001b[0;31mSystemError\u001b[0m                               Traceback (most recent call last)",
      "\u001b[0;32m~/ML_TERM/gym-micropolis-ga/micropolis/MicropolisCore/src/pyMicropolis/micropolisEngine/micropolisgenericengine.py\u001b[0m in \u001b[0;36minvokeCallback\u001b[0;34m(self, micropolis, name, *args)\u001b[0m\n\u001b[1;32m   1186\u001b[0m         \u001b[0;31m# In this case, micropolis is the same as self, so ignore it.\u001b[0m\u001b[0;34m\u001b[0m\u001b[0;34m\u001b[0m\u001b[0;34m\u001b[0m\u001b[0m\n\u001b[0;32m-> 1187\u001b[0;31m         \u001b[0mhandler\u001b[0m \u001b[0;34m=\u001b[0m \u001b[0mgetattr\u001b[0m\u001b[0;34m(\u001b[0m\u001b[0mself\u001b[0m\u001b[0;34m,\u001b[0m \u001b[0;34m'handle_'\u001b[0m \u001b[0;34m+\u001b[0m \u001b[0mname\u001b[0m\u001b[0;34m,\u001b[0m \u001b[0;32mNone\u001b[0m\u001b[0;34m)\u001b[0m\u001b[0;34m\u001b[0m\u001b[0;34m\u001b[0m\u001b[0m\n\u001b[0m\u001b[1;32m   1188\u001b[0m         \u001b[0;32mif\u001b[0m \u001b[0mhandler\u001b[0m\u001b[0;34m:\u001b[0m\u001b[0;34m\u001b[0m\u001b[0;34m\u001b[0m\u001b[0m\n",
      "\u001b[0;31mSystemError\u001b[0m: <built-in function getattr> returned a result with an error set",
      "\nThe above exception was the direct cause of the following exception:\n",
      "\u001b[0;31mSystemError\u001b[0m                               Traceback (most recent call last)",
      "\u001b[0;32m~/ML_TERM/gym-micropolis-ga/micropolis/MicropolisCore/src/pyMicropolis/micropolisEngine/micropolisgenericengine.py\u001b[0m in \u001b[0;36minvokeCallback\u001b[0;34m(self, micropolis, name, *args)\u001b[0m\n\u001b[1;32m   1186\u001b[0m         \u001b[0;31m# In this case, micropolis is the same as self, so ignore it.\u001b[0m\u001b[0;34m\u001b[0m\u001b[0;34m\u001b[0m\u001b[0;34m\u001b[0m\u001b[0m\n\u001b[0;32m-> 1187\u001b[0;31m         \u001b[0mhandler\u001b[0m \u001b[0;34m=\u001b[0m \u001b[0mgetattr\u001b[0m\u001b[0;34m(\u001b[0m\u001b[0mself\u001b[0m\u001b[0;34m,\u001b[0m \u001b[0;34m'handle_'\u001b[0m \u001b[0;34m+\u001b[0m \u001b[0mname\u001b[0m\u001b[0;34m,\u001b[0m \u001b[0;32mNone\u001b[0m\u001b[0;34m)\u001b[0m\u001b[0;34m\u001b[0m\u001b[0;34m\u001b[0m\u001b[0m\n\u001b[0m\u001b[1;32m   1188\u001b[0m         \u001b[0;32mif\u001b[0m \u001b[0mhandler\u001b[0m\u001b[0;34m:\u001b[0m\u001b[0;34m\u001b[0m\u001b[0;34m\u001b[0m\u001b[0m\n",
      "\u001b[0;31mSystemError\u001b[0m: <built-in function getattr> returned a result with an error set",
      "\nThe above exception was the direct cause of the following exception:\n",
      "\u001b[0;31mSystemError\u001b[0m                               Traceback (most recent call last)",
      "\u001b[0;32m~/ML_TERM/gym-micropolis-ga/micropolis/MicropolisCore/src/pyMicropolis/micropolisEngine/micropolisgenericengine.py\u001b[0m in \u001b[0;36minvokeCallback\u001b[0;34m(self, micropolis, name, *args)\u001b[0m\n\u001b[1;32m   1186\u001b[0m         \u001b[0;31m# In this case, micropolis is the same as self, so ignore it.\u001b[0m\u001b[0;34m\u001b[0m\u001b[0;34m\u001b[0m\u001b[0;34m\u001b[0m\u001b[0m\n\u001b[0;32m-> 1187\u001b[0;31m         \u001b[0mhandler\u001b[0m \u001b[0;34m=\u001b[0m \u001b[0mgetattr\u001b[0m\u001b[0;34m(\u001b[0m\u001b[0mself\u001b[0m\u001b[0;34m,\u001b[0m \u001b[0;34m'handle_'\u001b[0m \u001b[0;34m+\u001b[0m \u001b[0mname\u001b[0m\u001b[0;34m,\u001b[0m \u001b[0;32mNone\u001b[0m\u001b[0;34m)\u001b[0m\u001b[0;34m\u001b[0m\u001b[0;34m\u001b[0m\u001b[0m\n\u001b[0m\u001b[1;32m   1188\u001b[0m         \u001b[0;32mif\u001b[0m \u001b[0mhandler\u001b[0m\u001b[0;34m:\u001b[0m\u001b[0;34m\u001b[0m\u001b[0;34m\u001b[0m\u001b[0m\n",
      "\u001b[0;31mSystemError\u001b[0m: <built-in function getattr> returned a result with an error set",
      "\nThe above exception was the direct cause of the following exception:\n",
      "\u001b[0;31mSystemError\u001b[0m                               Traceback (most recent call last)",
      "\u001b[0;32m~/ML_TERM/gym-micropolis-ga/micropolis/MicropolisCore/src/pyMicropolis/micropolisEngine/micropolisgenericengine.py\u001b[0m in \u001b[0;36minvokeCallback\u001b[0;34m(self, micropolis, name, *args)\u001b[0m\n\u001b[1;32m   1186\u001b[0m         \u001b[0;31m# In this case, micropolis is the same as self, so ignore it.\u001b[0m\u001b[0;34m\u001b[0m\u001b[0;34m\u001b[0m\u001b[0;34m\u001b[0m\u001b[0m\n\u001b[0;32m-> 1187\u001b[0;31m         \u001b[0mhandler\u001b[0m \u001b[0;34m=\u001b[0m \u001b[0mgetattr\u001b[0m\u001b[0;34m(\u001b[0m\u001b[0mself\u001b[0m\u001b[0;34m,\u001b[0m \u001b[0;34m'handle_'\u001b[0m \u001b[0;34m+\u001b[0m \u001b[0mname\u001b[0m\u001b[0;34m,\u001b[0m \u001b[0;32mNone\u001b[0m\u001b[0;34m)\u001b[0m\u001b[0;34m\u001b[0m\u001b[0;34m\u001b[0m\u001b[0m\n\u001b[0m\u001b[1;32m   1188\u001b[0m         \u001b[0;32mif\u001b[0m \u001b[0mhandler\u001b[0m\u001b[0;34m:\u001b[0m\u001b[0;34m\u001b[0m\u001b[0;34m\u001b[0m\u001b[0m\n",
      "\u001b[0;31mSystemError\u001b[0m: <built-in function getattr> returned a result with an error set",
      "\nThe above exception was the direct cause of the following exception:\n",
      "\u001b[0;31mSystemError\u001b[0m                               Traceback (most recent call last)",
      "\u001b[0;32m~/ML_TERM/gym-micropolis-ga/micropolis/MicropolisCore/src/pyMicropolis/micropolisEngine/micropolisgenericengine.py\u001b[0m in \u001b[0;36minvokeCallback\u001b[0;34m(self, micropolis, name, *args)\u001b[0m\n\u001b[1;32m   1186\u001b[0m         \u001b[0;31m# In this case, micropolis is the same as self, so ignore it.\u001b[0m\u001b[0;34m\u001b[0m\u001b[0;34m\u001b[0m\u001b[0;34m\u001b[0m\u001b[0m\n\u001b[0;32m-> 1187\u001b[0;31m         \u001b[0mhandler\u001b[0m \u001b[0;34m=\u001b[0m \u001b[0mgetattr\u001b[0m\u001b[0;34m(\u001b[0m\u001b[0mself\u001b[0m\u001b[0;34m,\u001b[0m \u001b[0;34m'handle_'\u001b[0m \u001b[0;34m+\u001b[0m \u001b[0mname\u001b[0m\u001b[0;34m,\u001b[0m \u001b[0;32mNone\u001b[0m\u001b[0;34m)\u001b[0m\u001b[0;34m\u001b[0m\u001b[0;34m\u001b[0m\u001b[0m\n\u001b[0m\u001b[1;32m   1188\u001b[0m         \u001b[0;32mif\u001b[0m \u001b[0mhandler\u001b[0m\u001b[0;34m:\u001b[0m\u001b[0;34m\u001b[0m\u001b[0;34m\u001b[0m\u001b[0m\n",
      "\u001b[0;31mSystemError\u001b[0m: <built-in function getattr> returned a result with an error set",
      "\nThe above exception was the direct cause of the following exception:\n",
      "\u001b[0;31mSystemError\u001b[0m                               Traceback (most recent call last)",
      "\u001b[0;32m~/ML_TERM/gym-micropolis-ga/micropolis/MicropolisCore/src/pyMicropolis/micropolisEngine/micropolisgenericengine.py\u001b[0m in \u001b[0;36minvokeCallback\u001b[0;34m(self, micropolis, name, *args)\u001b[0m\n\u001b[1;32m   1186\u001b[0m         \u001b[0;31m# In this case, micropolis is the same as self, so ignore it.\u001b[0m\u001b[0;34m\u001b[0m\u001b[0;34m\u001b[0m\u001b[0;34m\u001b[0m\u001b[0m\n\u001b[0;32m-> 1187\u001b[0;31m         \u001b[0mhandler\u001b[0m \u001b[0;34m=\u001b[0m \u001b[0mgetattr\u001b[0m\u001b[0;34m(\u001b[0m\u001b[0mself\u001b[0m\u001b[0;34m,\u001b[0m \u001b[0;34m'handle_'\u001b[0m \u001b[0;34m+\u001b[0m \u001b[0mname\u001b[0m\u001b[0;34m,\u001b[0m \u001b[0;32mNone\u001b[0m\u001b[0;34m)\u001b[0m\u001b[0;34m\u001b[0m\u001b[0;34m\u001b[0m\u001b[0m\n\u001b[0m\u001b[1;32m   1188\u001b[0m         \u001b[0;32mif\u001b[0m \u001b[0mhandler\u001b[0m\u001b[0;34m:\u001b[0m\u001b[0;34m\u001b[0m\u001b[0;34m\u001b[0m\u001b[0m\n",
      "\u001b[0;31mSystemError\u001b[0m: <built-in function getattr> returned a result with an error set",
      "\nThe above exception was the direct cause of the following exception:\n",
      "\u001b[0;31mSystemError\u001b[0m                               Traceback (most recent call last)",
      "\u001b[0;32m~/ML_TERM/gym-micropolis-ga/micropolis/MicropolisCore/src/pyMicropolis/micropolisEngine/micropolisgenericengine.py\u001b[0m in \u001b[0;36minvokeCallback\u001b[0;34m(self, micropolis, name, *args)\u001b[0m\n\u001b[1;32m   1186\u001b[0m         \u001b[0;31m# In this case, micropolis is the same as self, so ignore it.\u001b[0m\u001b[0;34m\u001b[0m\u001b[0;34m\u001b[0m\u001b[0;34m\u001b[0m\u001b[0m\n\u001b[0;32m-> 1187\u001b[0;31m         \u001b[0mhandler\u001b[0m \u001b[0;34m=\u001b[0m \u001b[0mgetattr\u001b[0m\u001b[0;34m(\u001b[0m\u001b[0mself\u001b[0m\u001b[0;34m,\u001b[0m \u001b[0;34m'handle_'\u001b[0m \u001b[0;34m+\u001b[0m \u001b[0mname\u001b[0m\u001b[0;34m,\u001b[0m \u001b[0;32mNone\u001b[0m\u001b[0;34m)\u001b[0m\u001b[0;34m\u001b[0m\u001b[0;34m\u001b[0m\u001b[0m\n\u001b[0m\u001b[1;32m   1188\u001b[0m         \u001b[0;32mif\u001b[0m \u001b[0mhandler\u001b[0m\u001b[0;34m:\u001b[0m\u001b[0;34m\u001b[0m\u001b[0;34m\u001b[0m\u001b[0m\n",
      "\u001b[0;31mSystemError\u001b[0m: <built-in function getattr> returned a result with an error set",
      "\nThe above exception was the direct cause of the following exception:\n",
      "\u001b[0;31mSystemError\u001b[0m                               Traceback (most recent call last)",
      "\u001b[0;32m~/ML_TERM/gym-micropolis-ga/micropolis/MicropolisCore/src/pyMicropolis/micropolisEngine/micropolisgenericengine.py\u001b[0m in \u001b[0;36minvokeCallback\u001b[0;34m(self, micropolis, name, *args)\u001b[0m\n\u001b[1;32m   1186\u001b[0m         \u001b[0;31m# In this case, micropolis is the same as self, so ignore it.\u001b[0m\u001b[0;34m\u001b[0m\u001b[0;34m\u001b[0m\u001b[0;34m\u001b[0m\u001b[0m\n\u001b[0;32m-> 1187\u001b[0;31m         \u001b[0mhandler\u001b[0m \u001b[0;34m=\u001b[0m \u001b[0mgetattr\u001b[0m\u001b[0;34m(\u001b[0m\u001b[0mself\u001b[0m\u001b[0;34m,\u001b[0m \u001b[0;34m'handle_'\u001b[0m \u001b[0;34m+\u001b[0m \u001b[0mname\u001b[0m\u001b[0;34m,\u001b[0m \u001b[0;32mNone\u001b[0m\u001b[0;34m)\u001b[0m\u001b[0;34m\u001b[0m\u001b[0;34m\u001b[0m\u001b[0m\n\u001b[0m\u001b[1;32m   1188\u001b[0m         \u001b[0;32mif\u001b[0m \u001b[0mhandler\u001b[0m\u001b[0;34m:\u001b[0m\u001b[0;34m\u001b[0m\u001b[0;34m\u001b[0m\u001b[0m\n",
      "\u001b[0;31mSystemError\u001b[0m: <built-in function getattr> returned a result with an error set",
      "\nThe above exception was the direct cause of the following exception:\n",
      "\u001b[0;31mSystemError\u001b[0m                               Traceback (most recent call last)",
      "\u001b[0;32m~/ML_TERM/gym-micropolis-ga/micropolis/MicropolisCore/src/pyMicropolis/micropolisEngine/micropolisgenericengine.py\u001b[0m in \u001b[0;36minvokeCallback\u001b[0;34m(self, micropolis, name, *args)\u001b[0m\n\u001b[1;32m   1186\u001b[0m         \u001b[0;31m# In this case, micropolis is the same as self, so ignore it.\u001b[0m\u001b[0;34m\u001b[0m\u001b[0;34m\u001b[0m\u001b[0;34m\u001b[0m\u001b[0m\n\u001b[0;32m-> 1187\u001b[0;31m         \u001b[0mhandler\u001b[0m \u001b[0;34m=\u001b[0m \u001b[0mgetattr\u001b[0m\u001b[0;34m(\u001b[0m\u001b[0mself\u001b[0m\u001b[0;34m,\u001b[0m \u001b[0;34m'handle_'\u001b[0m \u001b[0;34m+\u001b[0m \u001b[0mname\u001b[0m\u001b[0;34m,\u001b[0m \u001b[0;32mNone\u001b[0m\u001b[0;34m)\u001b[0m\u001b[0;34m\u001b[0m\u001b[0;34m\u001b[0m\u001b[0m\n\u001b[0m\u001b[1;32m   1188\u001b[0m         \u001b[0;32mif\u001b[0m \u001b[0mhandler\u001b[0m\u001b[0;34m:\u001b[0m\u001b[0;34m\u001b[0m\u001b[0;34m\u001b[0m\u001b[0m\n",
      "\u001b[0;31mSystemError\u001b[0m: <built-in function getattr> returned a result with an error set",
      "\nThe above exception was the direct cause of the following exception:\n",
      "\u001b[0;31mSystemError\u001b[0m                               Traceback (most recent call last)",
      "\u001b[0;32m~/ML_TERM/gym-micropolis-ga/micropolis/MicropolisCore/src/pyMicropolis/micropolisEngine/micropolisgenericengine.py\u001b[0m in \u001b[0;36minvokeCallback\u001b[0;34m(self, micropolis, name, *args)\u001b[0m\n\u001b[1;32m   1186\u001b[0m         \u001b[0;31m# In this case, micropolis is the same as self, so ignore it.\u001b[0m\u001b[0;34m\u001b[0m\u001b[0;34m\u001b[0m\u001b[0;34m\u001b[0m\u001b[0m\n\u001b[0;32m-> 1187\u001b[0;31m         \u001b[0mhandler\u001b[0m \u001b[0;34m=\u001b[0m \u001b[0mgetattr\u001b[0m\u001b[0;34m(\u001b[0m\u001b[0mself\u001b[0m\u001b[0;34m,\u001b[0m \u001b[0;34m'handle_'\u001b[0m \u001b[0;34m+\u001b[0m \u001b[0mname\u001b[0m\u001b[0;34m,\u001b[0m \u001b[0;32mNone\u001b[0m\u001b[0;34m)\u001b[0m\u001b[0;34m\u001b[0m\u001b[0;34m\u001b[0m\u001b[0m\n\u001b[0m\u001b[1;32m   1188\u001b[0m         \u001b[0;32mif\u001b[0m \u001b[0mhandler\u001b[0m\u001b[0;34m:\u001b[0m\u001b[0;34m\u001b[0m\u001b[0;34m\u001b[0m\u001b[0m\n",
      "\u001b[0;31mSystemError\u001b[0m: <built-in function getattr> returned a result with an error set",
      "\nThe above exception was the direct cause of the following exception:\n",
      "\u001b[0;31mSystemError\u001b[0m                               Traceback (most recent call last)",
      "\u001b[0;32m~/ML_TERM/gym-micropolis-ga/micropolis/MicropolisCore/src/pyMicropolis/micropolisEngine/micropolisgenericengine.py\u001b[0m in \u001b[0;36minvokeCallback\u001b[0;34m(self, micropolis, name, *args)\u001b[0m\n\u001b[1;32m   1186\u001b[0m         \u001b[0;31m# In this case, micropolis is the same as self, so ignore it.\u001b[0m\u001b[0;34m\u001b[0m\u001b[0;34m\u001b[0m\u001b[0;34m\u001b[0m\u001b[0m\n\u001b[0;32m-> 1187\u001b[0;31m         \u001b[0mhandler\u001b[0m \u001b[0;34m=\u001b[0m \u001b[0mgetattr\u001b[0m\u001b[0;34m(\u001b[0m\u001b[0mself\u001b[0m\u001b[0;34m,\u001b[0m \u001b[0;34m'handle_'\u001b[0m \u001b[0;34m+\u001b[0m \u001b[0mname\u001b[0m\u001b[0;34m,\u001b[0m \u001b[0;32mNone\u001b[0m\u001b[0;34m)\u001b[0m\u001b[0;34m\u001b[0m\u001b[0;34m\u001b[0m\u001b[0m\n\u001b[0m\u001b[1;32m   1188\u001b[0m         \u001b[0;32mif\u001b[0m \u001b[0mhandler\u001b[0m\u001b[0;34m:\u001b[0m\u001b[0;34m\u001b[0m\u001b[0;34m\u001b[0m\u001b[0m\n",
      "\u001b[0;31mSystemError\u001b[0m: <built-in function getattr> returned a result with an error set",
      "\nThe above exception was the direct cause of the following exception:\n",
      "\u001b[0;31mSystemError\u001b[0m                               Traceback (most recent call last)",
      "\u001b[0;32m~/ML_TERM/gym-micropolis-ga/micropolis/MicropolisCore/src/pyMicropolis/micropolisEngine/micropolisgenericengine.py\u001b[0m in \u001b[0;36minvokeCallback\u001b[0;34m(self, micropolis, name, *args)\u001b[0m\n\u001b[1;32m   1186\u001b[0m         \u001b[0;31m# In this case, micropolis is the same as self, so ignore it.\u001b[0m\u001b[0;34m\u001b[0m\u001b[0;34m\u001b[0m\u001b[0;34m\u001b[0m\u001b[0m\n\u001b[0;32m-> 1187\u001b[0;31m         \u001b[0mhandler\u001b[0m \u001b[0;34m=\u001b[0m \u001b[0mgetattr\u001b[0m\u001b[0;34m(\u001b[0m\u001b[0mself\u001b[0m\u001b[0;34m,\u001b[0m \u001b[0;34m'handle_'\u001b[0m \u001b[0;34m+\u001b[0m \u001b[0mname\u001b[0m\u001b[0;34m,\u001b[0m \u001b[0;32mNone\u001b[0m\u001b[0;34m)\u001b[0m\u001b[0;34m\u001b[0m\u001b[0;34m\u001b[0m\u001b[0m\n\u001b[0m\u001b[1;32m   1188\u001b[0m         \u001b[0;32mif\u001b[0m \u001b[0mhandler\u001b[0m\u001b[0;34m:\u001b[0m\u001b[0;34m\u001b[0m\u001b[0;34m\u001b[0m\u001b[0m\n",
      "\u001b[0;31mSystemError\u001b[0m: <built-in function getattr> returned a result with an error set",
      "\nThe above exception was the direct cause of the following exception:\n",
      "\u001b[0;31mSystemError\u001b[0m                               Traceback (most recent call last)",
      "\u001b[0;32m~/ML_TERM/gym-micropolis-ga/micropolis/MicropolisCore/src/pyMicropolis/micropolisEngine/micropolisgenericengine.py\u001b[0m in \u001b[0;36minvokeCallback\u001b[0;34m(self, micropolis, name, *args)\u001b[0m\n\u001b[1;32m   1186\u001b[0m         \u001b[0;31m# In this case, micropolis is the same as self, so ignore it.\u001b[0m\u001b[0;34m\u001b[0m\u001b[0;34m\u001b[0m\u001b[0;34m\u001b[0m\u001b[0m\n\u001b[0;32m-> 1187\u001b[0;31m         \u001b[0mhandler\u001b[0m \u001b[0;34m=\u001b[0m \u001b[0mgetattr\u001b[0m\u001b[0;34m(\u001b[0m\u001b[0mself\u001b[0m\u001b[0;34m,\u001b[0m \u001b[0;34m'handle_'\u001b[0m \u001b[0;34m+\u001b[0m \u001b[0mname\u001b[0m\u001b[0;34m,\u001b[0m \u001b[0;32mNone\u001b[0m\u001b[0;34m)\u001b[0m\u001b[0;34m\u001b[0m\u001b[0;34m\u001b[0m\u001b[0m\n\u001b[0m\u001b[1;32m   1188\u001b[0m         \u001b[0;32mif\u001b[0m \u001b[0mhandler\u001b[0m\u001b[0;34m:\u001b[0m\u001b[0;34m\u001b[0m\u001b[0;34m\u001b[0m\u001b[0m\n",
      "\u001b[0;31mSystemError\u001b[0m: <built-in function getattr> returned a result with an error set",
      "\nThe above exception was the direct cause of the following exception:\n",
      "\u001b[0;31mSystemError\u001b[0m                               Traceback (most recent call last)",
      "\u001b[0;32m~/ML_TERM/gym-micropolis-ga/micropolis/MicropolisCore/src/pyMicropolis/micropolisEngine/micropolisgenericengine.py\u001b[0m in \u001b[0;36minvokeCallback\u001b[0;34m(self, micropolis, name, *args)\u001b[0m\n\u001b[1;32m   1186\u001b[0m         \u001b[0;31m# In this case, micropolis is the same as self, so ignore it.\u001b[0m\u001b[0;34m\u001b[0m\u001b[0;34m\u001b[0m\u001b[0;34m\u001b[0m\u001b[0m\n\u001b[0;32m-> 1187\u001b[0;31m         \u001b[0mhandler\u001b[0m \u001b[0;34m=\u001b[0m \u001b[0mgetattr\u001b[0m\u001b[0;34m(\u001b[0m\u001b[0mself\u001b[0m\u001b[0;34m,\u001b[0m \u001b[0;34m'handle_'\u001b[0m \u001b[0;34m+\u001b[0m \u001b[0mname\u001b[0m\u001b[0;34m,\u001b[0m \u001b[0;32mNone\u001b[0m\u001b[0;34m)\u001b[0m\u001b[0;34m\u001b[0m\u001b[0;34m\u001b[0m\u001b[0m\n\u001b[0m\u001b[1;32m   1188\u001b[0m         \u001b[0;32mif\u001b[0m \u001b[0mhandler\u001b[0m\u001b[0;34m:\u001b[0m\u001b[0;34m\u001b[0m\u001b[0;34m\u001b[0m\u001b[0m\n",
      "\u001b[0;31mSystemError\u001b[0m: <built-in function getattr> returned a result with an error set",
      "\nThe above exception was the direct cause of the following exception:\n",
      "\u001b[0;31mSystemError\u001b[0m                               Traceback (most recent call last)",
      "\u001b[0;32m~/ML_TERM/gym-micropolis-ga/micropolis/MicropolisCore/src/pyMicropolis/micropolisEngine/micropolisgenericengine.py\u001b[0m in \u001b[0;36minvokeCallback\u001b[0;34m(self, micropolis, name, *args)\u001b[0m\n\u001b[1;32m   1186\u001b[0m         \u001b[0;31m# In this case, micropolis is the same as self, so ignore it.\u001b[0m\u001b[0;34m\u001b[0m\u001b[0;34m\u001b[0m\u001b[0;34m\u001b[0m\u001b[0m\n\u001b[0;32m-> 1187\u001b[0;31m         \u001b[0mhandler\u001b[0m \u001b[0;34m=\u001b[0m \u001b[0mgetattr\u001b[0m\u001b[0;34m(\u001b[0m\u001b[0mself\u001b[0m\u001b[0;34m,\u001b[0m \u001b[0;34m'handle_'\u001b[0m \u001b[0;34m+\u001b[0m \u001b[0mname\u001b[0m\u001b[0;34m,\u001b[0m \u001b[0;32mNone\u001b[0m\u001b[0;34m)\u001b[0m\u001b[0;34m\u001b[0m\u001b[0;34m\u001b[0m\u001b[0m\n\u001b[0m\u001b[1;32m   1188\u001b[0m         \u001b[0;32mif\u001b[0m \u001b[0mhandler\u001b[0m\u001b[0;34m:\u001b[0m\u001b[0;34m\u001b[0m\u001b[0;34m\u001b[0m\u001b[0m\n",
      "\u001b[0;31mSystemError\u001b[0m: <built-in function getattr> returned a result with an error set",
      "\nThe above exception was the direct cause of the following exception:\n",
      "\u001b[0;31mSystemError\u001b[0m                               Traceback (most recent call last)",
      "\u001b[0;32m~/ML_TERM/gym-micropolis-ga/micropolis/MicropolisCore/src/pyMicropolis/micropolisEngine/micropolisgenericengine.py\u001b[0m in \u001b[0;36minvokeCallback\u001b[0;34m(self, micropolis, name, *args)\u001b[0m\n\u001b[1;32m   1186\u001b[0m         \u001b[0;31m# In this case, micropolis is the same as self, so ignore it.\u001b[0m\u001b[0;34m\u001b[0m\u001b[0;34m\u001b[0m\u001b[0;34m\u001b[0m\u001b[0m\n\u001b[0;32m-> 1187\u001b[0;31m         \u001b[0mhandler\u001b[0m \u001b[0;34m=\u001b[0m \u001b[0mgetattr\u001b[0m\u001b[0;34m(\u001b[0m\u001b[0mself\u001b[0m\u001b[0;34m,\u001b[0m \u001b[0;34m'handle_'\u001b[0m \u001b[0;34m+\u001b[0m \u001b[0mname\u001b[0m\u001b[0;34m,\u001b[0m \u001b[0;32mNone\u001b[0m\u001b[0;34m)\u001b[0m\u001b[0;34m\u001b[0m\u001b[0;34m\u001b[0m\u001b[0m\n\u001b[0m\u001b[1;32m   1188\u001b[0m         \u001b[0;32mif\u001b[0m \u001b[0mhandler\u001b[0m\u001b[0;34m:\u001b[0m\u001b[0;34m\u001b[0m\u001b[0;34m\u001b[0m\u001b[0m\n",
      "\u001b[0;31mSystemError\u001b[0m: <built-in function getattr> returned a result with an error set",
      "\nThe above exception was the direct cause of the following exception:\n",
      "\u001b[0;31mSystemError\u001b[0m                               Traceback (most recent call last)",
      "\u001b[0;32m~/ML_TERM/gym-micropolis-ga/micropolis/MicropolisCore/src/pyMicropolis/micropolisEngine/micropolisgenericengine.py\u001b[0m in \u001b[0;36minvokeCallback\u001b[0;34m(self, micropolis, name, *args)\u001b[0m\n\u001b[1;32m   1186\u001b[0m         \u001b[0;31m# In this case, micropolis is the same as self, so ignore it.\u001b[0m\u001b[0;34m\u001b[0m\u001b[0;34m\u001b[0m\u001b[0;34m\u001b[0m\u001b[0m\n\u001b[0;32m-> 1187\u001b[0;31m         \u001b[0mhandler\u001b[0m \u001b[0;34m=\u001b[0m \u001b[0mgetattr\u001b[0m\u001b[0;34m(\u001b[0m\u001b[0mself\u001b[0m\u001b[0;34m,\u001b[0m \u001b[0;34m'handle_'\u001b[0m \u001b[0;34m+\u001b[0m \u001b[0mname\u001b[0m\u001b[0;34m,\u001b[0m \u001b[0;32mNone\u001b[0m\u001b[0;34m)\u001b[0m\u001b[0;34m\u001b[0m\u001b[0;34m\u001b[0m\u001b[0m\n\u001b[0m\u001b[1;32m   1188\u001b[0m         \u001b[0;32mif\u001b[0m \u001b[0mhandler\u001b[0m\u001b[0;34m:\u001b[0m\u001b[0;34m\u001b[0m\u001b[0;34m\u001b[0m\u001b[0m\n",
      "\u001b[0;31mSystemError\u001b[0m: <built-in function getattr> returned a result with an error set",
      "\nThe above exception was the direct cause of the following exception:\n",
      "\u001b[0;31mSystemError\u001b[0m                               Traceback (most recent call last)",
      "\u001b[0;32m~/ML_TERM/gym-micropolis-ga/micropolis/MicropolisCore/src/pyMicropolis/micropolisEngine/micropolisgenericengine.py\u001b[0m in \u001b[0;36minvokeCallback\u001b[0;34m(self, micropolis, name, *args)\u001b[0m\n\u001b[1;32m   1186\u001b[0m         \u001b[0;31m# In this case, micropolis is the same as self, so ignore it.\u001b[0m\u001b[0;34m\u001b[0m\u001b[0;34m\u001b[0m\u001b[0;34m\u001b[0m\u001b[0m\n\u001b[0;32m-> 1187\u001b[0;31m         \u001b[0mhandler\u001b[0m \u001b[0;34m=\u001b[0m \u001b[0mgetattr\u001b[0m\u001b[0;34m(\u001b[0m\u001b[0mself\u001b[0m\u001b[0;34m,\u001b[0m \u001b[0;34m'handle_'\u001b[0m \u001b[0;34m+\u001b[0m \u001b[0mname\u001b[0m\u001b[0;34m,\u001b[0m \u001b[0;32mNone\u001b[0m\u001b[0;34m)\u001b[0m\u001b[0;34m\u001b[0m\u001b[0;34m\u001b[0m\u001b[0m\n\u001b[0m\u001b[1;32m   1188\u001b[0m         \u001b[0;32mif\u001b[0m \u001b[0mhandler\u001b[0m\u001b[0;34m:\u001b[0m\u001b[0;34m\u001b[0m\u001b[0;34m\u001b[0m\u001b[0m\n",
      "\u001b[0;31mSystemError\u001b[0m: <built-in function getattr> returned a result with an error set",
      "\nThe above exception was the direct cause of the following exception:\n",
      "\u001b[0;31mSystemError\u001b[0m                               Traceback (most recent call last)",
      "\u001b[0;32m~/ML_TERM/gym-micropolis-ga/micropolis/MicropolisCore/src/pyMicropolis/micropolisEngine/micropolisgenericengine.py\u001b[0m in \u001b[0;36minvokeCallback\u001b[0;34m(self, micropolis, name, *args)\u001b[0m\n\u001b[1;32m   1186\u001b[0m         \u001b[0;31m# In this case, micropolis is the same as self, so ignore it.\u001b[0m\u001b[0;34m\u001b[0m\u001b[0;34m\u001b[0m\u001b[0;34m\u001b[0m\u001b[0m\n\u001b[0;32m-> 1187\u001b[0;31m         \u001b[0mhandler\u001b[0m \u001b[0;34m=\u001b[0m \u001b[0mgetattr\u001b[0m\u001b[0;34m(\u001b[0m\u001b[0mself\u001b[0m\u001b[0;34m,\u001b[0m \u001b[0;34m'handle_'\u001b[0m \u001b[0;34m+\u001b[0m \u001b[0mname\u001b[0m\u001b[0;34m,\u001b[0m \u001b[0;32mNone\u001b[0m\u001b[0;34m)\u001b[0m\u001b[0;34m\u001b[0m\u001b[0;34m\u001b[0m\u001b[0m\n\u001b[0m\u001b[1;32m   1188\u001b[0m         \u001b[0;32mif\u001b[0m \u001b[0mhandler\u001b[0m\u001b[0;34m:\u001b[0m\u001b[0;34m\u001b[0m\u001b[0;34m\u001b[0m\u001b[0m\n",
      "\u001b[0;31mSystemError\u001b[0m: <built-in function getattr> returned a result with an error set",
      "\nThe above exception was the direct cause of the following exception:\n",
      "\u001b[0;31mSystemError\u001b[0m                               Traceback (most recent call last)",
      "\u001b[0;32m~/ML_TERM/gym-micropolis-ga/micropolis/MicropolisCore/src/pyMicropolis/micropolisEngine/micropolisgenericengine.py\u001b[0m in \u001b[0;36minvokeCallback\u001b[0;34m(self, micropolis, name, *args)\u001b[0m\n\u001b[1;32m   1186\u001b[0m         \u001b[0;31m# In this case, micropolis is the same as self, so ignore it.\u001b[0m\u001b[0;34m\u001b[0m\u001b[0;34m\u001b[0m\u001b[0;34m\u001b[0m\u001b[0m\n\u001b[0;32m-> 1187\u001b[0;31m         \u001b[0mhandler\u001b[0m \u001b[0;34m=\u001b[0m \u001b[0mgetattr\u001b[0m\u001b[0;34m(\u001b[0m\u001b[0mself\u001b[0m\u001b[0;34m,\u001b[0m \u001b[0;34m'handle_'\u001b[0m \u001b[0;34m+\u001b[0m \u001b[0mname\u001b[0m\u001b[0;34m,\u001b[0m \u001b[0;32mNone\u001b[0m\u001b[0;34m)\u001b[0m\u001b[0;34m\u001b[0m\u001b[0;34m\u001b[0m\u001b[0m\n\u001b[0m\u001b[1;32m   1188\u001b[0m         \u001b[0;32mif\u001b[0m \u001b[0mhandler\u001b[0m\u001b[0;34m:\u001b[0m\u001b[0;34m\u001b[0m\u001b[0;34m\u001b[0m\u001b[0m\n",
      "\u001b[0;31mSystemError\u001b[0m: <built-in function getattr> returned a result with an error set",
      "\nThe above exception was the direct cause of the following exception:\n",
      "\u001b[0;31mSystemError\u001b[0m                               Traceback (most recent call last)",
      "\u001b[0;32m~/ML_TERM/gym-micropolis-ga/micropolis/MicropolisCore/src/pyMicropolis/micropolisEngine/micropolisgenericengine.py\u001b[0m in \u001b[0;36minvokeCallback\u001b[0;34m(self, micropolis, name, *args)\u001b[0m\n\u001b[1;32m   1186\u001b[0m         \u001b[0;31m# In this case, micropolis is the same as self, so ignore it.\u001b[0m\u001b[0;34m\u001b[0m\u001b[0;34m\u001b[0m\u001b[0;34m\u001b[0m\u001b[0m\n\u001b[0;32m-> 1187\u001b[0;31m         \u001b[0mhandler\u001b[0m \u001b[0;34m=\u001b[0m \u001b[0mgetattr\u001b[0m\u001b[0;34m(\u001b[0m\u001b[0mself\u001b[0m\u001b[0;34m,\u001b[0m \u001b[0;34m'handle_'\u001b[0m \u001b[0;34m+\u001b[0m \u001b[0mname\u001b[0m\u001b[0;34m,\u001b[0m \u001b[0;32mNone\u001b[0m\u001b[0;34m)\u001b[0m\u001b[0;34m\u001b[0m\u001b[0;34m\u001b[0m\u001b[0m\n\u001b[0m\u001b[1;32m   1188\u001b[0m         \u001b[0;32mif\u001b[0m \u001b[0mhandler\u001b[0m\u001b[0;34m:\u001b[0m\u001b[0;34m\u001b[0m\u001b[0;34m\u001b[0m\u001b[0m\n",
      "\u001b[0;31mSystemError\u001b[0m: <built-in function getattr> returned a result with an error set",
      "\nThe above exception was the direct cause of the following exception:\n",
      "\u001b[0;31mSystemError\u001b[0m                               Traceback (most recent call last)",
      "\u001b[0;32m~/ML_TERM/gym-micropolis-ga/micropolis/MicropolisCore/src/pyMicropolis/micropolisEngine/micropolisgenericengine.py\u001b[0m in \u001b[0;36minvokeCallback\u001b[0;34m(self, micropolis, name, *args)\u001b[0m\n\u001b[1;32m   1186\u001b[0m         \u001b[0;31m# In this case, micropolis is the same as self, so ignore it.\u001b[0m\u001b[0;34m\u001b[0m\u001b[0;34m\u001b[0m\u001b[0;34m\u001b[0m\u001b[0m\n\u001b[0;32m-> 1187\u001b[0;31m         \u001b[0mhandler\u001b[0m \u001b[0;34m=\u001b[0m \u001b[0mgetattr\u001b[0m\u001b[0;34m(\u001b[0m\u001b[0mself\u001b[0m\u001b[0;34m,\u001b[0m \u001b[0;34m'handle_'\u001b[0m \u001b[0;34m+\u001b[0m \u001b[0mname\u001b[0m\u001b[0;34m,\u001b[0m \u001b[0;32mNone\u001b[0m\u001b[0;34m)\u001b[0m\u001b[0;34m\u001b[0m\u001b[0;34m\u001b[0m\u001b[0m\n\u001b[0m\u001b[1;32m   1188\u001b[0m         \u001b[0;32mif\u001b[0m \u001b[0mhandler\u001b[0m\u001b[0;34m:\u001b[0m\u001b[0;34m\u001b[0m\u001b[0;34m\u001b[0m\u001b[0m\n",
      "\u001b[0;31mSystemError\u001b[0m: <built-in function getattr> returned a result with an error set",
      "\nThe above exception was the direct cause of the following exception:\n",
      "\u001b[0;31mSystemError\u001b[0m                               Traceback (most recent call last)",
      "\u001b[0;32m~/ML_TERM/gym-micropolis-ga/micropolis/MicropolisCore/src/pyMicropolis/micropolisEngine/micropolisgenericengine.py\u001b[0m in \u001b[0;36minvokeCallback\u001b[0;34m(self, micropolis, name, *args)\u001b[0m\n\u001b[1;32m   1186\u001b[0m         \u001b[0;31m# In this case, micropolis is the same as self, so ignore it.\u001b[0m\u001b[0;34m\u001b[0m\u001b[0;34m\u001b[0m\u001b[0;34m\u001b[0m\u001b[0m\n\u001b[0;32m-> 1187\u001b[0;31m         \u001b[0mhandler\u001b[0m \u001b[0;34m=\u001b[0m \u001b[0mgetattr\u001b[0m\u001b[0;34m(\u001b[0m\u001b[0mself\u001b[0m\u001b[0;34m,\u001b[0m \u001b[0;34m'handle_'\u001b[0m \u001b[0;34m+\u001b[0m \u001b[0mname\u001b[0m\u001b[0;34m,\u001b[0m \u001b[0;32mNone\u001b[0m\u001b[0;34m)\u001b[0m\u001b[0;34m\u001b[0m\u001b[0;34m\u001b[0m\u001b[0m\n\u001b[0m\u001b[1;32m   1188\u001b[0m         \u001b[0;32mif\u001b[0m \u001b[0mhandler\u001b[0m\u001b[0;34m:\u001b[0m\u001b[0;34m\u001b[0m\u001b[0;34m\u001b[0m\u001b[0m\n",
      "\u001b[0;31mSystemError\u001b[0m: <built-in function getattr> returned a result with an error set",
      "\nThe above exception was the direct cause of the following exception:\n",
      "\u001b[0;31mSystemError\u001b[0m                               Traceback (most recent call last)",
      "\u001b[0;32m~/ML_TERM/gym-micropolis-ga/micropolis/MicropolisCore/src/pyMicropolis/micropolisEngine/micropolisgenericengine.py\u001b[0m in \u001b[0;36minvokeCallback\u001b[0;34m(self, micropolis, name, *args)\u001b[0m\n\u001b[1;32m   1186\u001b[0m         \u001b[0;31m# In this case, micropolis is the same as self, so ignore it.\u001b[0m\u001b[0;34m\u001b[0m\u001b[0;34m\u001b[0m\u001b[0;34m\u001b[0m\u001b[0m\n\u001b[0;32m-> 1187\u001b[0;31m         \u001b[0mhandler\u001b[0m \u001b[0;34m=\u001b[0m \u001b[0mgetattr\u001b[0m\u001b[0;34m(\u001b[0m\u001b[0mself\u001b[0m\u001b[0;34m,\u001b[0m \u001b[0;34m'handle_'\u001b[0m \u001b[0;34m+\u001b[0m \u001b[0mname\u001b[0m\u001b[0;34m,\u001b[0m \u001b[0;32mNone\u001b[0m\u001b[0;34m)\u001b[0m\u001b[0;34m\u001b[0m\u001b[0;34m\u001b[0m\u001b[0m\n\u001b[0m\u001b[1;32m   1188\u001b[0m         \u001b[0;32mif\u001b[0m \u001b[0mhandler\u001b[0m\u001b[0;34m:\u001b[0m\u001b[0;34m\u001b[0m\u001b[0;34m\u001b[0m\u001b[0m\n",
      "\u001b[0;31mSystemError\u001b[0m: <built-in function getattr> returned a result with an error set",
      "\nThe above exception was the direct cause of the following exception:\n",
      "\u001b[0;31mSystemError\u001b[0m                               Traceback (most recent call last)",
      "\u001b[0;32m~/ML_TERM/gym-micropolis-ga/micropolis/MicropolisCore/src/pyMicropolis/micropolisEngine/micropolisgenericengine.py\u001b[0m in \u001b[0;36minvokeCallback\u001b[0;34m(self, micropolis, name, *args)\u001b[0m\n\u001b[1;32m   1186\u001b[0m         \u001b[0;31m# In this case, micropolis is the same as self, so ignore it.\u001b[0m\u001b[0;34m\u001b[0m\u001b[0;34m\u001b[0m\u001b[0;34m\u001b[0m\u001b[0m\n\u001b[0;32m-> 1187\u001b[0;31m         \u001b[0mhandler\u001b[0m \u001b[0;34m=\u001b[0m \u001b[0mgetattr\u001b[0m\u001b[0;34m(\u001b[0m\u001b[0mself\u001b[0m\u001b[0;34m,\u001b[0m \u001b[0;34m'handle_'\u001b[0m \u001b[0;34m+\u001b[0m \u001b[0mname\u001b[0m\u001b[0;34m,\u001b[0m \u001b[0;32mNone\u001b[0m\u001b[0;34m)\u001b[0m\u001b[0;34m\u001b[0m\u001b[0;34m\u001b[0m\u001b[0m\n\u001b[0m\u001b[1;32m   1188\u001b[0m         \u001b[0;32mif\u001b[0m \u001b[0mhandler\u001b[0m\u001b[0;34m:\u001b[0m\u001b[0;34m\u001b[0m\u001b[0;34m\u001b[0m\u001b[0m\n",
      "\u001b[0;31mSystemError\u001b[0m: <built-in function getattr> returned a result with an error set",
      "\nThe above exception was the direct cause of the following exception:\n",
      "\u001b[0;31mSystemError\u001b[0m                               Traceback (most recent call last)",
      "\u001b[0;32m~/ML_TERM/gym-micropolis-ga/micropolis/MicropolisCore/src/pyMicropolis/micropolisEngine/micropolisgenericengine.py\u001b[0m in \u001b[0;36minvokeCallback\u001b[0;34m(self, micropolis, name, *args)\u001b[0m\n\u001b[1;32m   1186\u001b[0m         \u001b[0;31m# In this case, micropolis is the same as self, so ignore it.\u001b[0m\u001b[0;34m\u001b[0m\u001b[0;34m\u001b[0m\u001b[0;34m\u001b[0m\u001b[0m\n\u001b[0;32m-> 1187\u001b[0;31m         \u001b[0mhandler\u001b[0m \u001b[0;34m=\u001b[0m \u001b[0mgetattr\u001b[0m\u001b[0;34m(\u001b[0m\u001b[0mself\u001b[0m\u001b[0;34m,\u001b[0m \u001b[0;34m'handle_'\u001b[0m \u001b[0;34m+\u001b[0m \u001b[0mname\u001b[0m\u001b[0;34m,\u001b[0m \u001b[0;32mNone\u001b[0m\u001b[0;34m)\u001b[0m\u001b[0;34m\u001b[0m\u001b[0;34m\u001b[0m\u001b[0m\n\u001b[0m\u001b[1;32m   1188\u001b[0m         \u001b[0;32mif\u001b[0m \u001b[0mhandler\u001b[0m\u001b[0;34m:\u001b[0m\u001b[0;34m\u001b[0m\u001b[0;34m\u001b[0m\u001b[0m\n",
      "\u001b[0;31mSystemError\u001b[0m: <built-in function getattr> returned a result with an error set",
      "\nThe above exception was the direct cause of the following exception:\n",
      "\u001b[0;31mSystemError\u001b[0m                               Traceback (most recent call last)",
      "\u001b[0;32m~/ML_TERM/gym-micropolis-ga/micropolis/MicropolisCore/src/pyMicropolis/micropolisEngine/micropolisgenericengine.py\u001b[0m in \u001b[0;36minvokeCallback\u001b[0;34m(self, micropolis, name, *args)\u001b[0m\n\u001b[1;32m   1186\u001b[0m         \u001b[0;31m# In this case, micropolis is the same as self, so ignore it.\u001b[0m\u001b[0;34m\u001b[0m\u001b[0;34m\u001b[0m\u001b[0;34m\u001b[0m\u001b[0m\n\u001b[0;32m-> 1187\u001b[0;31m         \u001b[0mhandler\u001b[0m \u001b[0;34m=\u001b[0m \u001b[0mgetattr\u001b[0m\u001b[0;34m(\u001b[0m\u001b[0mself\u001b[0m\u001b[0;34m,\u001b[0m \u001b[0;34m'handle_'\u001b[0m \u001b[0;34m+\u001b[0m \u001b[0mname\u001b[0m\u001b[0;34m,\u001b[0m \u001b[0;32mNone\u001b[0m\u001b[0;34m)\u001b[0m\u001b[0;34m\u001b[0m\u001b[0;34m\u001b[0m\u001b[0m\n\u001b[0m\u001b[1;32m   1188\u001b[0m         \u001b[0;32mif\u001b[0m \u001b[0mhandler\u001b[0m\u001b[0;34m:\u001b[0m\u001b[0;34m\u001b[0m\u001b[0;34m\u001b[0m\u001b[0m\n",
      "\u001b[0;31mSystemError\u001b[0m: <built-in function getattr> returned a result with an error set",
      "\nThe above exception was the direct cause of the following exception:\n",
      "\u001b[0;31mSystemError\u001b[0m                               Traceback (most recent call last)",
      "\u001b[0;32m~/ML_TERM/gym-micropolis-ga/micropolis/MicropolisCore/src/pyMicropolis/micropolisEngine/micropolisgenericengine.py\u001b[0m in \u001b[0;36minvokeCallback\u001b[0;34m(self, micropolis, name, *args)\u001b[0m\n\u001b[1;32m   1186\u001b[0m         \u001b[0;31m# In this case, micropolis is the same as self, so ignore it.\u001b[0m\u001b[0;34m\u001b[0m\u001b[0;34m\u001b[0m\u001b[0;34m\u001b[0m\u001b[0m\n\u001b[0;32m-> 1187\u001b[0;31m         \u001b[0mhandler\u001b[0m \u001b[0;34m=\u001b[0m \u001b[0mgetattr\u001b[0m\u001b[0;34m(\u001b[0m\u001b[0mself\u001b[0m\u001b[0;34m,\u001b[0m \u001b[0;34m'handle_'\u001b[0m \u001b[0;34m+\u001b[0m \u001b[0mname\u001b[0m\u001b[0;34m,\u001b[0m \u001b[0;32mNone\u001b[0m\u001b[0;34m)\u001b[0m\u001b[0;34m\u001b[0m\u001b[0;34m\u001b[0m\u001b[0m\n\u001b[0m\u001b[1;32m   1188\u001b[0m         \u001b[0;32mif\u001b[0m \u001b[0mhandler\u001b[0m\u001b[0;34m:\u001b[0m\u001b[0;34m\u001b[0m\u001b[0;34m\u001b[0m\u001b[0m\n",
      "\u001b[0;31mSystemError\u001b[0m: <built-in function getattr> returned a result with an error set",
      "\nThe above exception was the direct cause of the following exception:\n",
      "\u001b[0;31mSystemError\u001b[0m                               Traceback (most recent call last)",
      "\u001b[0;32m~/ML_TERM/gym-micropolis-ga/micropolis/MicropolisCore/src/pyMicropolis/micropolisEngine/micropolisgenericengine.py\u001b[0m in \u001b[0;36minvokeCallback\u001b[0;34m(self, micropolis, name, *args)\u001b[0m\n\u001b[1;32m   1186\u001b[0m         \u001b[0;31m# In this case, micropolis is the same as self, so ignore it.\u001b[0m\u001b[0;34m\u001b[0m\u001b[0;34m\u001b[0m\u001b[0;34m\u001b[0m\u001b[0m\n\u001b[0;32m-> 1187\u001b[0;31m         \u001b[0mhandler\u001b[0m \u001b[0;34m=\u001b[0m \u001b[0mgetattr\u001b[0m\u001b[0;34m(\u001b[0m\u001b[0mself\u001b[0m\u001b[0;34m,\u001b[0m \u001b[0;34m'handle_'\u001b[0m \u001b[0;34m+\u001b[0m \u001b[0mname\u001b[0m\u001b[0;34m,\u001b[0m \u001b[0;32mNone\u001b[0m\u001b[0;34m)\u001b[0m\u001b[0;34m\u001b[0m\u001b[0;34m\u001b[0m\u001b[0m\n\u001b[0m\u001b[1;32m   1188\u001b[0m         \u001b[0;32mif\u001b[0m \u001b[0mhandler\u001b[0m\u001b[0;34m:\u001b[0m\u001b[0;34m\u001b[0m\u001b[0;34m\u001b[0m\u001b[0m\n",
      "\u001b[0;31mSystemError\u001b[0m: <built-in function getattr> returned a result with an error set",
      "\nThe above exception was the direct cause of the following exception:\n",
      "\u001b[0;31mSystemError\u001b[0m                               Traceback (most recent call last)",
      "\u001b[0;32m~/ML_TERM/gym-micropolis-ga/micropolis/MicropolisCore/src/pyMicropolis/micropolisEngine/micropolisgenericengine.py\u001b[0m in \u001b[0;36minvokeCallback\u001b[0;34m(self, micropolis, name, *args)\u001b[0m\n\u001b[1;32m   1186\u001b[0m         \u001b[0;31m# In this case, micropolis is the same as self, so ignore it.\u001b[0m\u001b[0;34m\u001b[0m\u001b[0;34m\u001b[0m\u001b[0;34m\u001b[0m\u001b[0m\n\u001b[0;32m-> 1187\u001b[0;31m         \u001b[0mhandler\u001b[0m \u001b[0;34m=\u001b[0m \u001b[0mgetattr\u001b[0m\u001b[0;34m(\u001b[0m\u001b[0mself\u001b[0m\u001b[0;34m,\u001b[0m \u001b[0;34m'handle_'\u001b[0m \u001b[0;34m+\u001b[0m \u001b[0mname\u001b[0m\u001b[0;34m,\u001b[0m \u001b[0;32mNone\u001b[0m\u001b[0;34m)\u001b[0m\u001b[0;34m\u001b[0m\u001b[0;34m\u001b[0m\u001b[0m\n\u001b[0m\u001b[1;32m   1188\u001b[0m         \u001b[0;32mif\u001b[0m \u001b[0mhandler\u001b[0m\u001b[0;34m:\u001b[0m\u001b[0;34m\u001b[0m\u001b[0;34m\u001b[0m\u001b[0m\n",
      "\u001b[0;31mSystemError\u001b[0m: <built-in function getattr> returned a result with an error set",
      "\nThe above exception was the direct cause of the following exception:\n",
      "\u001b[0;31mSystemError\u001b[0m                               Traceback (most recent call last)",
      "\u001b[0;32m~/ML_TERM/gym-micropolis-ga/micropolis/MicropolisCore/src/pyMicropolis/micropolisEngine/micropolisgenericengine.py\u001b[0m in \u001b[0;36minvokeCallback\u001b[0;34m(self, micropolis, name, *args)\u001b[0m\n\u001b[1;32m   1186\u001b[0m         \u001b[0;31m# In this case, micropolis is the same as self, so ignore it.\u001b[0m\u001b[0;34m\u001b[0m\u001b[0;34m\u001b[0m\u001b[0;34m\u001b[0m\u001b[0m\n\u001b[0;32m-> 1187\u001b[0;31m         \u001b[0mhandler\u001b[0m \u001b[0;34m=\u001b[0m \u001b[0mgetattr\u001b[0m\u001b[0;34m(\u001b[0m\u001b[0mself\u001b[0m\u001b[0;34m,\u001b[0m \u001b[0;34m'handle_'\u001b[0m \u001b[0;34m+\u001b[0m \u001b[0mname\u001b[0m\u001b[0;34m,\u001b[0m \u001b[0;32mNone\u001b[0m\u001b[0;34m)\u001b[0m\u001b[0;34m\u001b[0m\u001b[0;34m\u001b[0m\u001b[0m\n\u001b[0m\u001b[1;32m   1188\u001b[0m         \u001b[0;32mif\u001b[0m \u001b[0mhandler\u001b[0m\u001b[0;34m:\u001b[0m\u001b[0;34m\u001b[0m\u001b[0;34m\u001b[0m\u001b[0m\n",
      "\u001b[0;31mSystemError\u001b[0m: <built-in function getattr> returned a result with an error set",
      "\nThe above exception was the direct cause of the following exception:\n",
      "\u001b[0;31mSystemError\u001b[0m                               Traceback (most recent call last)",
      "\u001b[0;32m~/ML_TERM/gym-micropolis-ga/micropolis/MicropolisCore/src/pyMicropolis/micropolisEngine/micropolisgenericengine.py\u001b[0m in \u001b[0;36minvokeCallback\u001b[0;34m(self, micropolis, name, *args)\u001b[0m\n\u001b[1;32m   1186\u001b[0m         \u001b[0;31m# In this case, micropolis is the same as self, so ignore it.\u001b[0m\u001b[0;34m\u001b[0m\u001b[0;34m\u001b[0m\u001b[0;34m\u001b[0m\u001b[0m\n\u001b[0;32m-> 1187\u001b[0;31m         \u001b[0mhandler\u001b[0m \u001b[0;34m=\u001b[0m \u001b[0mgetattr\u001b[0m\u001b[0;34m(\u001b[0m\u001b[0mself\u001b[0m\u001b[0;34m,\u001b[0m \u001b[0;34m'handle_'\u001b[0m \u001b[0;34m+\u001b[0m \u001b[0mname\u001b[0m\u001b[0;34m,\u001b[0m \u001b[0;32mNone\u001b[0m\u001b[0;34m)\u001b[0m\u001b[0;34m\u001b[0m\u001b[0;34m\u001b[0m\u001b[0m\n\u001b[0m\u001b[1;32m   1188\u001b[0m         \u001b[0;32mif\u001b[0m \u001b[0mhandler\u001b[0m\u001b[0;34m:\u001b[0m\u001b[0;34m\u001b[0m\u001b[0;34m\u001b[0m\u001b[0m\n",
      "\u001b[0;31mSystemError\u001b[0m: <built-in function getattr> returned a result with an error set",
      "\nThe above exception was the direct cause of the following exception:\n",
      "\u001b[0;31mSystemError\u001b[0m                               Traceback (most recent call last)",
      "\u001b[0;32m~/ML_TERM/gym-micropolis-ga/micropolis/MicropolisCore/src/pyMicropolis/micropolisEngine/micropolisgenericengine.py\u001b[0m in \u001b[0;36minvokeCallback\u001b[0;34m(self, micropolis, name, *args)\u001b[0m\n\u001b[1;32m   1186\u001b[0m         \u001b[0;31m# In this case, micropolis is the same as self, so ignore it.\u001b[0m\u001b[0;34m\u001b[0m\u001b[0;34m\u001b[0m\u001b[0;34m\u001b[0m\u001b[0m\n\u001b[0;32m-> 1187\u001b[0;31m         \u001b[0mhandler\u001b[0m \u001b[0;34m=\u001b[0m \u001b[0mgetattr\u001b[0m\u001b[0;34m(\u001b[0m\u001b[0mself\u001b[0m\u001b[0;34m,\u001b[0m \u001b[0;34m'handle_'\u001b[0m \u001b[0;34m+\u001b[0m \u001b[0mname\u001b[0m\u001b[0;34m,\u001b[0m \u001b[0;32mNone\u001b[0m\u001b[0;34m)\u001b[0m\u001b[0;34m\u001b[0m\u001b[0;34m\u001b[0m\u001b[0m\n\u001b[0m\u001b[1;32m   1188\u001b[0m         \u001b[0;32mif\u001b[0m \u001b[0mhandler\u001b[0m\u001b[0;34m:\u001b[0m\u001b[0;34m\u001b[0m\u001b[0;34m\u001b[0m\u001b[0m\n",
      "\u001b[0;31mSystemError\u001b[0m: <built-in function getattr> returned a result with an error set",
      "\nThe above exception was the direct cause of the following exception:\n",
      "\u001b[0;31mSystemError\u001b[0m                               Traceback (most recent call last)",
      "\u001b[0;32m~/ML_TERM/gym-micropolis-ga/micropolis/MicropolisCore/src/pyMicropolis/micropolisEngine/micropolisgenericengine.py\u001b[0m in \u001b[0;36minvokeCallback\u001b[0;34m(self, micropolis, name, *args)\u001b[0m\n\u001b[1;32m   1186\u001b[0m         \u001b[0;31m# In this case, micropolis is the same as self, so ignore it.\u001b[0m\u001b[0;34m\u001b[0m\u001b[0;34m\u001b[0m\u001b[0;34m\u001b[0m\u001b[0m\n\u001b[0;32m-> 1187\u001b[0;31m         \u001b[0mhandler\u001b[0m \u001b[0;34m=\u001b[0m \u001b[0mgetattr\u001b[0m\u001b[0;34m(\u001b[0m\u001b[0mself\u001b[0m\u001b[0;34m,\u001b[0m \u001b[0;34m'handle_'\u001b[0m \u001b[0;34m+\u001b[0m \u001b[0mname\u001b[0m\u001b[0;34m,\u001b[0m \u001b[0;32mNone\u001b[0m\u001b[0;34m)\u001b[0m\u001b[0;34m\u001b[0m\u001b[0;34m\u001b[0m\u001b[0m\n\u001b[0m\u001b[1;32m   1188\u001b[0m         \u001b[0;32mif\u001b[0m \u001b[0mhandler\u001b[0m\u001b[0;34m:\u001b[0m\u001b[0;34m\u001b[0m\u001b[0;34m\u001b[0m\u001b[0m\n",
      "\u001b[0;31mSystemError\u001b[0m: <built-in function getattr> returned a result with an error set",
      "\nThe above exception was the direct cause of the following exception:\n",
      "\u001b[0;31mSystemError\u001b[0m                               Traceback (most recent call last)",
      "\u001b[0;32m~/ML_TERM/gym-micropolis-ga/micropolis/MicropolisCore/src/pyMicropolis/micropolisEngine/micropolisgenericengine.py\u001b[0m in \u001b[0;36minvokeCallback\u001b[0;34m(self, micropolis, name, *args)\u001b[0m\n\u001b[1;32m   1186\u001b[0m         \u001b[0;31m# In this case, micropolis is the same as self, so ignore it.\u001b[0m\u001b[0;34m\u001b[0m\u001b[0;34m\u001b[0m\u001b[0;34m\u001b[0m\u001b[0m\n\u001b[0;32m-> 1187\u001b[0;31m         \u001b[0mhandler\u001b[0m \u001b[0;34m=\u001b[0m \u001b[0mgetattr\u001b[0m\u001b[0;34m(\u001b[0m\u001b[0mself\u001b[0m\u001b[0;34m,\u001b[0m \u001b[0;34m'handle_'\u001b[0m \u001b[0;34m+\u001b[0m \u001b[0mname\u001b[0m\u001b[0;34m,\u001b[0m \u001b[0;32mNone\u001b[0m\u001b[0;34m)\u001b[0m\u001b[0;34m\u001b[0m\u001b[0;34m\u001b[0m\u001b[0m\n\u001b[0m\u001b[1;32m   1188\u001b[0m         \u001b[0;32mif\u001b[0m \u001b[0mhandler\u001b[0m\u001b[0;34m:\u001b[0m\u001b[0;34m\u001b[0m\u001b[0;34m\u001b[0m\u001b[0m\n",
      "\u001b[0;31mSystemError\u001b[0m: <built-in function getattr> returned a result with an error set",
      "\nThe above exception was the direct cause of the following exception:\n",
      "\u001b[0;31mSystemError\u001b[0m                               Traceback (most recent call last)",
      "\u001b[0;32m~/ML_TERM/gym-micropolis-ga/micropolis/MicropolisCore/src/pyMicropolis/micropolisEngine/micropolisgenericengine.py\u001b[0m in \u001b[0;36minvokeCallback\u001b[0;34m(self, micropolis, name, *args)\u001b[0m\n\u001b[1;32m   1186\u001b[0m         \u001b[0;31m# In this case, micropolis is the same as self, so ignore it.\u001b[0m\u001b[0;34m\u001b[0m\u001b[0;34m\u001b[0m\u001b[0;34m\u001b[0m\u001b[0m\n\u001b[0;32m-> 1187\u001b[0;31m         \u001b[0mhandler\u001b[0m \u001b[0;34m=\u001b[0m \u001b[0mgetattr\u001b[0m\u001b[0;34m(\u001b[0m\u001b[0mself\u001b[0m\u001b[0;34m,\u001b[0m \u001b[0;34m'handle_'\u001b[0m \u001b[0;34m+\u001b[0m \u001b[0mname\u001b[0m\u001b[0;34m,\u001b[0m \u001b[0;32mNone\u001b[0m\u001b[0;34m)\u001b[0m\u001b[0;34m\u001b[0m\u001b[0;34m\u001b[0m\u001b[0m\n\u001b[0m\u001b[1;32m   1188\u001b[0m         \u001b[0;32mif\u001b[0m \u001b[0mhandler\u001b[0m\u001b[0;34m:\u001b[0m\u001b[0;34m\u001b[0m\u001b[0;34m\u001b[0m\u001b[0m\n",
      "\u001b[0;31mSystemError\u001b[0m: <built-in function getattr> returned a result with an error set",
      "\nThe above exception was the direct cause of the following exception:\n",
      "\u001b[0;31mSystemError\u001b[0m                               Traceback (most recent call last)",
      "\u001b[0;32m~/ML_TERM/gym-micropolis-ga/micropolis/MicropolisCore/src/pyMicropolis/micropolisEngine/micropolisgenericengine.py\u001b[0m in \u001b[0;36minvokeCallback\u001b[0;34m(self, micropolis, name, *args)\u001b[0m\n\u001b[1;32m   1186\u001b[0m         \u001b[0;31m# In this case, micropolis is the same as self, so ignore it.\u001b[0m\u001b[0;34m\u001b[0m\u001b[0;34m\u001b[0m\u001b[0;34m\u001b[0m\u001b[0m\n\u001b[0;32m-> 1187\u001b[0;31m         \u001b[0mhandler\u001b[0m \u001b[0;34m=\u001b[0m \u001b[0mgetattr\u001b[0m\u001b[0;34m(\u001b[0m\u001b[0mself\u001b[0m\u001b[0;34m,\u001b[0m \u001b[0;34m'handle_'\u001b[0m \u001b[0;34m+\u001b[0m \u001b[0mname\u001b[0m\u001b[0;34m,\u001b[0m \u001b[0;32mNone\u001b[0m\u001b[0;34m)\u001b[0m\u001b[0;34m\u001b[0m\u001b[0;34m\u001b[0m\u001b[0m\n\u001b[0m\u001b[1;32m   1188\u001b[0m         \u001b[0;32mif\u001b[0m \u001b[0mhandler\u001b[0m\u001b[0;34m:\u001b[0m\u001b[0;34m\u001b[0m\u001b[0;34m\u001b[0m\u001b[0m\n",
      "\u001b[0;31mSystemError\u001b[0m: <built-in function getattr> returned a result with an error set",
      "\nThe above exception was the direct cause of the following exception:\n",
      "\u001b[0;31mSystemError\u001b[0m                               Traceback (most recent call last)",
      "\u001b[0;32m~/ML_TERM/gym-micropolis-ga/micropolis/MicropolisCore/src/pyMicropolis/micropolisEngine/micropolisgenericengine.py\u001b[0m in \u001b[0;36minvokeCallback\u001b[0;34m(self, micropolis, name, *args)\u001b[0m\n\u001b[1;32m   1186\u001b[0m         \u001b[0;31m# In this case, micropolis is the same as self, so ignore it.\u001b[0m\u001b[0;34m\u001b[0m\u001b[0;34m\u001b[0m\u001b[0;34m\u001b[0m\u001b[0m\n\u001b[0;32m-> 1187\u001b[0;31m         \u001b[0mhandler\u001b[0m \u001b[0;34m=\u001b[0m \u001b[0mgetattr\u001b[0m\u001b[0;34m(\u001b[0m\u001b[0mself\u001b[0m\u001b[0;34m,\u001b[0m \u001b[0;34m'handle_'\u001b[0m \u001b[0;34m+\u001b[0m \u001b[0mname\u001b[0m\u001b[0;34m,\u001b[0m \u001b[0;32mNone\u001b[0m\u001b[0;34m)\u001b[0m\u001b[0;34m\u001b[0m\u001b[0;34m\u001b[0m\u001b[0m\n\u001b[0m\u001b[1;32m   1188\u001b[0m         \u001b[0;32mif\u001b[0m \u001b[0mhandler\u001b[0m\u001b[0;34m:\u001b[0m\u001b[0;34m\u001b[0m\u001b[0;34m\u001b[0m\u001b[0m\n",
      "\u001b[0;31mSystemError\u001b[0m: <built-in function getattr> returned a result with an error set",
      "\nThe above exception was the direct cause of the following exception:\n",
      "\u001b[0;31mSystemError\u001b[0m                               Traceback (most recent call last)",
      "\u001b[0;32m~/ML_TERM/gym-micropolis-ga/micropolis/MicropolisCore/src/pyMicropolis/micropolisEngine/micropolisgenericengine.py\u001b[0m in \u001b[0;36minvokeCallback\u001b[0;34m(self, micropolis, name, *args)\u001b[0m\n\u001b[1;32m   1186\u001b[0m         \u001b[0;31m# In this case, micropolis is the same as self, so ignore it.\u001b[0m\u001b[0;34m\u001b[0m\u001b[0;34m\u001b[0m\u001b[0;34m\u001b[0m\u001b[0m\n\u001b[0;32m-> 1187\u001b[0;31m         \u001b[0mhandler\u001b[0m \u001b[0;34m=\u001b[0m \u001b[0mgetattr\u001b[0m\u001b[0;34m(\u001b[0m\u001b[0mself\u001b[0m\u001b[0;34m,\u001b[0m \u001b[0;34m'handle_'\u001b[0m \u001b[0;34m+\u001b[0m \u001b[0mname\u001b[0m\u001b[0;34m,\u001b[0m \u001b[0;32mNone\u001b[0m\u001b[0;34m)\u001b[0m\u001b[0;34m\u001b[0m\u001b[0;34m\u001b[0m\u001b[0m\n\u001b[0m\u001b[1;32m   1188\u001b[0m         \u001b[0;32mif\u001b[0m \u001b[0mhandler\u001b[0m\u001b[0;34m:\u001b[0m\u001b[0;34m\u001b[0m\u001b[0;34m\u001b[0m\u001b[0m\n",
      "\u001b[0;31mSystemError\u001b[0m: <built-in function getattr> returned a result with an error set",
      "\nThe above exception was the direct cause of the following exception:\n",
      "\u001b[0;31mSystemError\u001b[0m                               Traceback (most recent call last)",
      "\u001b[0;32m~/ML_TERM/gym-micropolis-ga/micropolis/MicropolisCore/src/pyMicropolis/micropolisEngine/micropolisgenericengine.py\u001b[0m in \u001b[0;36minvokeCallback\u001b[0;34m(self, micropolis, name, *args)\u001b[0m\n\u001b[1;32m   1186\u001b[0m         \u001b[0;31m# In this case, micropolis is the same as self, so ignore it.\u001b[0m\u001b[0;34m\u001b[0m\u001b[0;34m\u001b[0m\u001b[0;34m\u001b[0m\u001b[0m\n\u001b[0;32m-> 1187\u001b[0;31m         \u001b[0mhandler\u001b[0m \u001b[0;34m=\u001b[0m \u001b[0mgetattr\u001b[0m\u001b[0;34m(\u001b[0m\u001b[0mself\u001b[0m\u001b[0;34m,\u001b[0m \u001b[0;34m'handle_'\u001b[0m \u001b[0;34m+\u001b[0m \u001b[0mname\u001b[0m\u001b[0;34m,\u001b[0m \u001b[0;32mNone\u001b[0m\u001b[0;34m)\u001b[0m\u001b[0;34m\u001b[0m\u001b[0;34m\u001b[0m\u001b[0m\n\u001b[0m\u001b[1;32m   1188\u001b[0m         \u001b[0;32mif\u001b[0m \u001b[0mhandler\u001b[0m\u001b[0;34m:\u001b[0m\u001b[0;34m\u001b[0m\u001b[0;34m\u001b[0m\u001b[0m\n",
      "\u001b[0;31mSystemError\u001b[0m: <built-in function getattr> returned a result with an error set",
      "\nThe above exception was the direct cause of the following exception:\n",
      "\u001b[0;31mSystemError\u001b[0m                               Traceback (most recent call last)",
      "\u001b[0;32m~/ML_TERM/gym-micropolis-ga/micropolis/MicropolisCore/src/pyMicropolis/micropolisEngine/micropolisgenericengine.py\u001b[0m in \u001b[0;36minvokeCallback\u001b[0;34m(self, micropolis, name, *args)\u001b[0m\n\u001b[1;32m   1186\u001b[0m         \u001b[0;31m# In this case, micropolis is the same as self, so ignore it.\u001b[0m\u001b[0;34m\u001b[0m\u001b[0;34m\u001b[0m\u001b[0;34m\u001b[0m\u001b[0m\n\u001b[0;32m-> 1187\u001b[0;31m         \u001b[0mhandler\u001b[0m \u001b[0;34m=\u001b[0m \u001b[0mgetattr\u001b[0m\u001b[0;34m(\u001b[0m\u001b[0mself\u001b[0m\u001b[0;34m,\u001b[0m \u001b[0;34m'handle_'\u001b[0m \u001b[0;34m+\u001b[0m \u001b[0mname\u001b[0m\u001b[0;34m,\u001b[0m \u001b[0;32mNone\u001b[0m\u001b[0;34m)\u001b[0m\u001b[0;34m\u001b[0m\u001b[0;34m\u001b[0m\u001b[0m\n\u001b[0m\u001b[1;32m   1188\u001b[0m         \u001b[0;32mif\u001b[0m \u001b[0mhandler\u001b[0m\u001b[0;34m:\u001b[0m\u001b[0;34m\u001b[0m\u001b[0;34m\u001b[0m\u001b[0m\n",
      "\u001b[0;31mSystemError\u001b[0m: <built-in function getattr> returned a result with an error set",
      "\nThe above exception was the direct cause of the following exception:\n",
      "\u001b[0;31mSystemError\u001b[0m                               Traceback (most recent call last)",
      "\u001b[0;32m~/ML_TERM/gym-micropolis-ga/micropolis/MicropolisCore/src/pyMicropolis/micropolisEngine/micropolisgenericengine.py\u001b[0m in \u001b[0;36minvokeCallback\u001b[0;34m(self, micropolis, name, *args)\u001b[0m\n\u001b[1;32m   1186\u001b[0m         \u001b[0;31m# In this case, micropolis is the same as self, so ignore it.\u001b[0m\u001b[0;34m\u001b[0m\u001b[0;34m\u001b[0m\u001b[0;34m\u001b[0m\u001b[0m\n\u001b[0;32m-> 1187\u001b[0;31m         \u001b[0mhandler\u001b[0m \u001b[0;34m=\u001b[0m \u001b[0mgetattr\u001b[0m\u001b[0;34m(\u001b[0m\u001b[0mself\u001b[0m\u001b[0;34m,\u001b[0m \u001b[0;34m'handle_'\u001b[0m \u001b[0;34m+\u001b[0m \u001b[0mname\u001b[0m\u001b[0;34m,\u001b[0m \u001b[0;32mNone\u001b[0m\u001b[0;34m)\u001b[0m\u001b[0;34m\u001b[0m\u001b[0;34m\u001b[0m\u001b[0m\n\u001b[0m\u001b[1;32m   1188\u001b[0m         \u001b[0;32mif\u001b[0m \u001b[0mhandler\u001b[0m\u001b[0;34m:\u001b[0m\u001b[0;34m\u001b[0m\u001b[0;34m\u001b[0m\u001b[0m\n",
      "\u001b[0;31mSystemError\u001b[0m: <built-in function getattr> returned a result with an error set",
      "\nThe above exception was the direct cause of the following exception:\n",
      "\u001b[0;31mSystemError\u001b[0m                               Traceback (most recent call last)",
      "\u001b[0;32m~/ML_TERM/gym-micropolis-ga/micropolis/MicropolisCore/src/pyMicropolis/micropolisEngine/micropolisgenericengine.py\u001b[0m in \u001b[0;36minvokeCallback\u001b[0;34m(self, micropolis, name, *args)\u001b[0m\n\u001b[1;32m   1186\u001b[0m         \u001b[0;31m# In this case, micropolis is the same as self, so ignore it.\u001b[0m\u001b[0;34m\u001b[0m\u001b[0;34m\u001b[0m\u001b[0;34m\u001b[0m\u001b[0m\n\u001b[0;32m-> 1187\u001b[0;31m         \u001b[0mhandler\u001b[0m \u001b[0;34m=\u001b[0m \u001b[0mgetattr\u001b[0m\u001b[0;34m(\u001b[0m\u001b[0mself\u001b[0m\u001b[0;34m,\u001b[0m \u001b[0;34m'handle_'\u001b[0m \u001b[0;34m+\u001b[0m \u001b[0mname\u001b[0m\u001b[0;34m,\u001b[0m \u001b[0;32mNone\u001b[0m\u001b[0;34m)\u001b[0m\u001b[0;34m\u001b[0m\u001b[0;34m\u001b[0m\u001b[0m\n\u001b[0m\u001b[1;32m   1188\u001b[0m         \u001b[0;32mif\u001b[0m \u001b[0mhandler\u001b[0m\u001b[0;34m:\u001b[0m\u001b[0;34m\u001b[0m\u001b[0;34m\u001b[0m\u001b[0m\n",
      "\u001b[0;31mSystemError\u001b[0m: <built-in function getattr> returned a result with an error set",
      "\nThe above exception was the direct cause of the following exception:\n",
      "\u001b[0;31mSystemError\u001b[0m                               Traceback (most recent call last)",
      "\u001b[0;32m<ipython-input-4-f014dccafaa0>\u001b[0m in \u001b[0;36m<module>\u001b[0;34m\u001b[0m\n\u001b[1;32m      3\u001b[0m \u001b[0mbest_pop\u001b[0m \u001b[0;34m=\u001b[0m \u001b[0;34m[\u001b[0m\u001b[0;34m]\u001b[0m\u001b[0;34m\u001b[0m\u001b[0;34m\u001b[0m\u001b[0m\n\u001b[1;32m      4\u001b[0m \u001b[0;32mfor\u001b[0m \u001b[0mi\u001b[0m \u001b[0;32min\u001b[0m \u001b[0mrange\u001b[0m\u001b[0;34m(\u001b[0m\u001b[0;36m10\u001b[0m\u001b[0;34m)\u001b[0m \u001b[0;34m:\u001b[0m\u001b[0;34m\u001b[0m\u001b[0;34m\u001b[0m\u001b[0m\n\u001b[0;32m----> 5\u001b[0;31m     \u001b[0mq\u001b[0m\u001b[0;34m.\u001b[0m\u001b[0mevaluate_all\u001b[0m\u001b[0;34m(\u001b[0m\u001b[0;34m)\u001b[0m\u001b[0;34m\u001b[0m\u001b[0;34m\u001b[0m\u001b[0m\n\u001b[0m\u001b[1;32m      6\u001b[0m     \u001b[0mranked_genomes\u001b[0m \u001b[0;34m=\u001b[0m \u001b[0;34m[\u001b[0m\u001b[0mx\u001b[0m \u001b[0;32mfor\u001b[0m \u001b[0m_\u001b[0m\u001b[0;34m,\u001b[0m\u001b[0mx\u001b[0m \u001b[0;32min\u001b[0m \u001b[0msorted\u001b[0m\u001b[0;34m(\u001b[0m\u001b[0mzip\u001b[0m\u001b[0;34m(\u001b[0m\u001b[0mq\u001b[0m\u001b[0;34m.\u001b[0m\u001b[0mpopulations\u001b[0m\u001b[0;34m,\u001b[0m\u001b[0mq\u001b[0m\u001b[0;34m.\u001b[0m\u001b[0mgenomes\u001b[0m\u001b[0;34m)\u001b[0m\u001b[0;34m)\u001b[0m\u001b[0;34m]\u001b[0m\u001b[0;34m\u001b[0m\u001b[0;34m\u001b[0m\u001b[0m\n\u001b[1;32m      7\u001b[0m     \u001b[0mparents\u001b[0m \u001b[0;34m=\u001b[0m \u001b[0mranked_genomes\u001b[0m\u001b[0;34m[\u001b[0m\u001b[0;34m:\u001b[0m\u001b[0mint\u001b[0m\u001b[0;34m(\u001b[0m\u001b[0mround\u001b[0m\u001b[0;34m(\u001b[0m\u001b[0mlen\u001b[0m\u001b[0;34m(\u001b[0m\u001b[0mranked_genomes\u001b[0m\u001b[0;34m)\u001b[0m\u001b[0;34m*\u001b[0m\u001b[0mp_selection\u001b[0m\u001b[0;34m)\u001b[0m\u001b[0;34m)\u001b[0m\u001b[0;34m]\u001b[0m\u001b[0;34m\u001b[0m\u001b[0;34m\u001b[0m\u001b[0m\n",
      "\u001b[0;32m~/ML_TERM/gym-micropolis-ga/MicropolisControlScript.py\u001b[0m in \u001b[0;36mevaluate_all\u001b[0;34m(self)\u001b[0m\n\u001b[1;32m     92\u001b[0m         \u001b[0;32mfor\u001b[0m \u001b[0mg\u001b[0m \u001b[0;32min\u001b[0m \u001b[0mself\u001b[0m\u001b[0;34m.\u001b[0m\u001b[0mgenomes\u001b[0m\u001b[0;34m:\u001b[0m\u001b[0;34m\u001b[0m\u001b[0;34m\u001b[0m\u001b[0m\n\u001b[1;32m     93\u001b[0m \u001b[0;34m\u001b[0m\u001b[0m\n\u001b[0;32m---> 94\u001b[0;31m             \u001b[0mself\u001b[0m\u001b[0;34m.\u001b[0m\u001b[0mpopulations\u001b[0m\u001b[0;34m.\u001b[0m\u001b[0mappend\u001b[0m\u001b[0;34m(\u001b[0m\u001b[0mself\u001b[0m\u001b[0;34m.\u001b[0m\u001b[0mevaluate\u001b[0m\u001b[0;34m(\u001b[0m\u001b[0mg\u001b[0m\u001b[0;34m,\u001b[0m \u001b[0mdisplay\u001b[0m\u001b[0;34m=\u001b[0m\u001b[0;32mFalse\u001b[0m\u001b[0;34m)\u001b[0m\u001b[0;34m)\u001b[0m\u001b[0;34m\u001b[0m\u001b[0;34m\u001b[0m\u001b[0m\n\u001b[0m\u001b[1;32m     95\u001b[0m \u001b[0;34m\u001b[0m\u001b[0m\n",
      "\u001b[0;32m~/ML_TERM/gym-micropolis-ga/MicropolisControlScript.py\u001b[0m in \u001b[0;36mevaluate\u001b[0;34m(self, g1, display)\u001b[0m\n\u001b[1;32m     63\u001b[0m         \u001b[0mm\u001b[0m \u001b[0;34m=\u001b[0m \u001b[0mself\u001b[0m\u001b[0;34m.\u001b[0m\u001b[0mbuild_city\u001b[0m\u001b[0;34m(\u001b[0m\u001b[0mg1\u001b[0m\u001b[0;34m,\u001b[0m\u001b[0mdisplay\u001b[0m\u001b[0;34m)\u001b[0m\u001b[0;34m\u001b[0m\u001b[0;34m\u001b[0m\u001b[0m\n\u001b[1;32m     64\u001b[0m         \u001b[0;32mfor\u001b[0m \u001b[0mi\u001b[0m \u001b[0;32min\u001b[0m \u001b[0mrange\u001b[0m\u001b[0;34m(\u001b[0m\u001b[0mself\u001b[0m\u001b[0;34m.\u001b[0m\u001b[0mn_steps_evaluation\u001b[0m\u001b[0;34m)\u001b[0m \u001b[0;34m:\u001b[0m\u001b[0;34m\u001b[0m\u001b[0;34m\u001b[0m\u001b[0m\n\u001b[0;32m---> 65\u001b[0;31m             \u001b[0mm\u001b[0m\u001b[0;34m.\u001b[0m\u001b[0mengine\u001b[0m\u001b[0;34m.\u001b[0m\u001b[0msimTick\u001b[0m\u001b[0;34m(\u001b[0m\u001b[0;34m)\u001b[0m\u001b[0;34m\u001b[0m\u001b[0;34m\u001b[0m\u001b[0m\n\u001b[0m\u001b[1;32m     66\u001b[0m             \u001b[0;32mif\u001b[0m \u001b[0mdisplay\u001b[0m \u001b[0;34m:\u001b[0m \u001b[0mm\u001b[0m\u001b[0;34m.\u001b[0m\u001b[0mrender\u001b[0m\u001b[0;34m(\u001b[0m\u001b[0;34m)\u001b[0m\u001b[0;34m\u001b[0m\u001b[0;34m\u001b[0m\u001b[0m\n\u001b[1;32m     67\u001b[0m         \u001b[0;32mif\u001b[0m \u001b[0mdisplay\u001b[0m \u001b[0;34m:\u001b[0m\u001b[0;34m\u001b[0m\u001b[0;34m\u001b[0m\u001b[0m\n",
      "\u001b[0;32m~/ML_TERM/gym-micropolis-ga/micropolis/MicropolisCore/src/pyMicropolis/micropolisEngine/micropolisengine.py\u001b[0m in \u001b[0;36msimTick\u001b[0;34m(self)\u001b[0m\n\u001b[1;32m   1257\u001b[0m \u001b[0;34m\u001b[0m\u001b[0m\n\u001b[1;32m   1258\u001b[0m     \u001b[0;32mdef\u001b[0m \u001b[0msimTick\u001b[0m\u001b[0;34m(\u001b[0m\u001b[0mself\u001b[0m\u001b[0;34m)\u001b[0m \u001b[0;34m->\u001b[0m \u001b[0;34m\"void\"\u001b[0m\u001b[0;34m:\u001b[0m\u001b[0;34m\u001b[0m\u001b[0;34m\u001b[0m\u001b[0m\n\u001b[0;32m-> 1259\u001b[0;31m         \u001b[0;32mreturn\u001b[0m \u001b[0m_micropolisengine\u001b[0m\u001b[0;34m.\u001b[0m\u001b[0mMicropolis_simTick\u001b[0m\u001b[0;34m(\u001b[0m\u001b[0mself\u001b[0m\u001b[0;34m)\u001b[0m\u001b[0;34m\u001b[0m\u001b[0;34m\u001b[0m\u001b[0m\n\u001b[0m\u001b[1;32m   1260\u001b[0m \u001b[0;34m\u001b[0m\u001b[0m\n\u001b[1;32m   1261\u001b[0m     \u001b[0;32mdef\u001b[0m \u001b[0msimRobots\u001b[0m\u001b[0;34m(\u001b[0m\u001b[0mself\u001b[0m\u001b[0;34m)\u001b[0m \u001b[0;34m->\u001b[0m \u001b[0;34m\"void\"\u001b[0m\u001b[0;34m:\u001b[0m\u001b[0;34m\u001b[0m\u001b[0;34m\u001b[0m\u001b[0m\n",
      "\u001b[0;31mSystemError\u001b[0m: <built-in function Micropolis_simTick> returned a result with an error set"
     ]
    }
   ],
   "source": [
    "%%capture\n",
    "p_selection = 0.2\n",
    "n_mutations = 10\n",
    "best_pop = []\n",
    "for i in range(10) :\n",
    "    q.evaluate_all()\n",
    "    ranked_genomes = [x for _,x in sorted(zip(q.populations,q.genomes))]\n",
    "    parents = ranked_genomes[:int(round(len(ranked_genomes)*p_selection))]\n",
    "    children = list()\n",
    "    best_pop.append(np.max(q.populations))\n",
    "    while len(children) < q.n_population :\n",
    "        i = np.random.randint(0,len(parents))\n",
    "        j = np.random.randint(0,len(parents))\n",
    "        if i!=j : \n",
    "            children.append(q.mate(parents[i],parents[j]))\n",
    "    # Apply mutations\n",
    "    idxs = list(range(q.n_population))\n",
    "    random.shuffle(idxs)\n",
    "    for a in idxs[0:n_mutations] : \n",
    "        q.mutate_genome(children[a])\n",
    "    q.genomes = children"
   ]
  },
  {
   "cell_type": "code",
   "execution_count": 25,
   "metadata": {
    "ExecuteTime": {
     "end_time": "2019-04-16T05:15:03.554968Z",
     "start_time": "2019-04-16T05:15:03.542725Z"
    },
    "pycharm": {}
   },
   "outputs": [
    {
     "data": {
      "text/plain": [
       "[1520, 1100, 940, 1240, 880, 1080, 780, 600, 720, 640]"
      ]
     },
     "execution_count": 25,
     "metadata": {},
     "output_type": "execute_result"
    }
   ],
   "source": [
    "best_pop"
   ]
  }
 ],
 "metadata": {
  "kernelspec": {
   "display_name": "PyCharm (gym-micropolis-ga)",
   "language": "python",
   "name": "pycharm-5c1987d2"
  },
  "language_info": {
   "codemirror_mode": {
    "name": "ipython",
    "version": 3
   },
   "file_extension": ".py",
   "mimetype": "text/x-python",
   "name": "python",
   "nbconvert_exporter": "python",
   "pygments_lexer": "ipython3",
   "version": "3.6.7"
  }
 },
 "nbformat": 4,
 "nbformat_minor": 2
}
